{"type":"subscribed","id":1,"msg":{"channel":"orderbook_delta","sid":1}}
{"type":"orderbook_snapshot","sid":1,"seq":1,"msg":{"market_ticker":"KXFEDDECISION-26SEP-H25","market_id":"749202d4-2a9a-4c24-b73a-116af982e245","yes_dollars_fp":[["0.0100","357122.00"],["0.0200","45136.10"],["0.0300","9976.05"],["0.0400","17777.00"],["0.0500","281.00"],["0.0600","42.71"],["0.0700","6407.77"],["0.0800","1119.96"],["0.0900","10917.43"],["0.1000","13644.80"],["0.1100","939.72"],["0.1200","202.59"],["0.1300","173.23"],["0.1400","234.46"],["0.1500","8.86"],["0.1800","601.63"],["0.2000","850.00"],["0.2100","2.20"],["0.2200","205.70"],["0.2500","8474.44"],["0.2600","1.00"],["0.2900","327.35"],["0.3300","1.73"],["0.3400","338.41"],["0.3500","2520.21"],["0.3600","473.48"],["0.3700","6542.89"],["0.4000","917.13"],["0.4100","180.00"],["0.4300","747.10"],["0.4700","53.00"],["0.4800","59.00"],["0.4900","2055.00"],["0.5000","8167.00"],["0.5100","25.00"],["0.5200","366.00"],["0.5500","526.50"],["0.5600","300.00"],["0.5700","74.00"],["0.6000","20.00"],["0.7400","52.00"],["0.7500","1029.00"],["0.7600","700.00"],["0.7700","36292.88"],["0.7800","115931.00"],["0.7900","3742.46"],["0.8000","114059.74"]],"no_dollars_fp":[["0.0100","349755.75"],["0.0200","24119.09"],["0.0300","17673.05"],["0.0400","25997.92"],["0.0500","21770.85"],["0.0600","17851.55"],["0.0700","12474.01"],["0.0800","2207.05"],["0.0900","10407.36"],["0.1000","35491.68"],["0.1100","14162.78"],["0.1200","958.02"],["0.1300","1847.53"],["0.1400","14668.43"],["0.1500","39553.25"],["0.1600","25162.00"],["0.1700","19987.00"],["0.1800","22240.57"],["0.1900","574.00"]]}}
{"type":"orderbook_delta","sid":1,"seq":2,"msg":{"market_ticker":"KXFEDDECISION-26SEP-H25","market_id":"749202d4-2a9a-4c24-b73a-116af982e245","price_dollars":"0.8000","delta_fp":"-94.69","side":"yes","ts":"2026-09-11T15:33:23.355178Z","ts_ms":1789140803355}}
{"type":"orderbook_delta","sid":1,"seq":3,"msg":{"market_ticker":"KXFEDDECISION-26SEP-H25","market_id":"749202d4-2a9a-4c24-b73a-116af982e245","price_dollars":"0.8000","delta_fp":"-200.00","side":"yes","ts":"2026-09-11T15:33:23.38318Z","ts_ms":1789140803383}}
{"type":"orderbook_delta","sid":1,"seq":4,"msg":{"market_ticker":"KXFEDDECISION-26SEP-H25","market_id":"749202d4-2a9a-4c24-b73a-116af982e245","price_dollars":"0.1400","delta_fp":"-141.00","side":"no","ts":"2026-09-11T15:33:23.395062Z","ts_ms":1789140803395}}
{"type":"orderbook_delta","sid":1,"seq":5,"msg":{"market_ticker":"KXFEDDECISION-26SEP-H25","market_id":"749202d4-2a9a-4c24-b73a-116af982e245","price_dollars":"0.7900","delta_fp":"200.00","side":"yes","ts":"2026-09-11T15:33:23.405732Z","ts_ms":1789140803405}}
{"type":"orderbook_delta","sid":1,"seq":6,"msg":{"market_ticker":"KXFEDDECISION-26SEP-H25","market_id":"749202d4-2a9a-4c24-b73a-116af982e245","price_dollars":"0.1500","delta_fp":"141.00","side":"no","ts":"2026-09-11T15:33:23.41774Z","ts_ms":1789140803417}}
{"type":"orderbook_delta","sid":1,"seq":7,"msg":{"market_ticker":"KXFEDDECISION-26SEP-H25","market_id":"749202d4-2a9a-4c24-b73a-116af982e245","price_dollars":"0.1800","delta_fp":"2.00","side":"no","ts":"2026-09-11T15:33:25.019728Z","ts_ms":1789140805019}}
{"type":"orderbook_delta","sid":1,"seq":8,"msg":{"market_ticker":"KXFEDDECISION-26SEP-H25","market_id":"749202d4-2a9a-4c24-b73a-116af982e245","price_dollars":"0.1800","delta_fp":"-2.00","side":"no","ts":"2026-09-11T15:33:33.018434Z","ts_ms":1789140813018}}
{"type":"orderbook_delta","sid":1,"seq":9,"msg":{"market_ticker":"KXFEDDECISION-26SEP-H25","market_id":"749202d4-2a9a-4c24-b73a-116af982e245","price_dollars":"0.8000","delta_fp":"-2.13","side":"yes","ts":"2026-09-11T15:33:42.24453Z","ts_ms":1789140822244}}
{"type":"orderbook_delta","sid":1,"seq":10,"msg":{"market_ticker":"KXFEDDECISION-26SEP-H25","market_id":"749202d4-2a9a-4c24-b73a-116af982e245","price_dollars":"0.7900","delta_fp":"-200.00","side":"yes","ts":"2026-09-11T15:33:44.314647Z","ts_ms":1789140824314}}
{"type":"orderbook_delta","sid":1,"seq":11,"msg":{"market_ticker":"KXFEDDECISION-26SEP-H25","market_id":"749202d4-2a9a-4c24-b73a-116af982e245","price_dollars":"0.1500","delta_fp":"-141.00","side":"no","ts":"2026-09-11T15:33:44.320587Z","ts_ms":1789140824320}}
{"type":"orderbook_delta","sid":1,"seq":12,"msg":{"market_ticker":"KXFEDDECISION-26SEP-H25","market_id":"749202d4-2a9a-4c24-b73a-116af982e245","price_dollars":"0.8000","delta_fp":"200.00","side":"yes","ts":"2026-09-11T15:33:44.352105Z","ts_ms":1789140824352}}
{"type":"orderbook_delta","sid":1,"seq":13,"msg":{"market_ticker":"KXFEDDECISION-26SEP-H25","market_id":"749202d4-2a9a-4c24-b73a-116af982e245","price_dollars":"0.1400","delta_fp":"141.00","side":"no","ts":"2026-09-11T15:33:44.366315Z","ts_ms":1789140824366}}
{"type":"orderbook_delta","sid":1,"seq":14,"msg":{"market_ticker":"KXFEDDECISION-26SEP-H25","market_id":"749202d4-2a9a-4c24-b73a-116af982e245","price_dollars":"0.1800","delta_fp":"2.00","side":"no","ts":"2026-09-11T15:33:45.019292Z","ts_ms":1789140825019}}
{"type":"orderbook_delta","sid":1,"seq":15,"msg":{"market_ticker":"KXFEDDECISION-26SEP-H25","market_id":"749202d4-2a9a-4c24-b73a-116af982e245","price_dollars":"0.8000","delta_fp":"-200.00","side":"yes","ts":"2026-09-11T15:33:49.649375Z","ts_ms":1789140829649}}
{"type":"orderbook_delta","sid":1,"seq":16,"msg":{"market_ticker":"KXFEDDECISION-26SEP-H25","market_id":"749202d4-2a9a-4c24-b73a-116af982e245","price_dollars":"0.1400","delta_fp":"-141.00","side":"no","ts":"2026-09-11T15:33:49.659426Z","ts_ms":1789140829659}}
{"type":"orderbook_delta","sid":1,"seq":17,"msg":{"market_ticker":"KXFEDDECISION-26SEP-H25","market_id":"749202d4-2a9a-4c24-b73a-116af982e245","price_dollars":"0.7900","delta_fp":"200.00","side":"yes","ts":"2026-09-11T15:33:49.690099Z","ts_ms":1789140829690}}
{"type":"orderbook_delta","sid":1,"seq":18,"msg":{"market_ticker":"KXFEDDECISION-26SEP-H25","market_id":"749202d4-2a9a-4c24-b73a-116af982e245","price_dollars":"0.1500","delta_fp":"141.00","side":"no","ts":"2026-09-11T15:33:49.700628Z","ts_ms":1789140829700}}
{"type":"orderbook_delta","sid":1,"seq":19,"msg":{"market_ticker":"KXFEDDECISION-26SEP-H25","market_id":"749202d4-2a9a-4c24-b73a-116af982e245","price_dollars":"0.1800","delta_fp":"-2.00","side":"no","ts":"2026-09-11T15:33:52.24803Z","ts_ms":1789140832248}}
{"type":"orderbook_delta","sid":1,"seq":20,"msg":{"market_ticker":"KXFEDDECISION-26SEP-H25","market_id":"749202d4-2a9a-4c24-b73a-116af982e245","price_dollars":"0.1600","delta_fp":"1500.00","side":"no","ts":"2026-09-11T15:33:53.718435Z","ts_ms":1789140833718}}
{"type":"orderbook_delta","sid":1,"seq":21,"msg":{"market_ticker":"KXFEDDECISION-26SEP-H25","market_id":"749202d4-2a9a-4c24-b73a-116af982e245","price_dollars":"0.1400","delta_fp":"-186.00","side":"no","ts":"2026-09-11T15:33:53.719499Z","ts_ms":1789140833719}}
{"type":"orderbook_delta","sid":1,"seq":22,"msg":{"market_ticker":"KXFEDDECISION-26SEP-H25","market_id":"749202d4-2a9a-4c24-b73a-116af982e245","price_dollars":"0.8000","delta_fp":"-4405.74","side":"yes","ts":"2026-09-11T15:33:59.671984Z","ts_ms":1789140839671}}
{"type":"orderbook_delta","sid":1,"seq":23,"msg":{"market_ticker":"KXFEDDECISION-26SEP-H25","market_id":"749202d4-2a9a-4c24-b73a-116af982e245","price_dollars":"0.8000","delta_fp":"-234.41","side":"yes","ts":"2026-09-11T15:33:59.671984Z","ts_ms":1789140839671}}
{"type":"orderbook_delta","sid":1,"seq":24,"msg":{"market_ticker":"KXFEDDECISION-26SEP-H25","market_id":"749202d4-2a9a-4c24-b73a-116af982e245","price_dollars":"0.7900","delta_fp":"-200.00","side":"yes","ts":"2026-09-11T15:33:59.691965Z","ts_ms":1789140839691}}
{"type":"orderbook_delta","sid":1,"seq":25,"msg":{"market_ticker":"KXFEDDECISION-26SEP-H25","market_id":"749202d4-2a9a-4c24-b73a-116af982e245","price_dollars":"0.1500","delta_fp":"-141.00","side":"no","ts":"2026-09-11T15:33:59.703303Z","ts_ms":1789140839703}}
{"type":"orderbook_delta","sid":1,"seq":26,"msg":{"market_ticker":"KXFEDDECISION-26SEP-H25","market_id":"749202d4-2a9a-4c24-b73a-116af982e245","price_dollars":"0.8000","delta_fp":"200.00","side":"yes","ts":"2026-09-11T15:33:59.713517Z","ts_ms":1789140839713}}
{"type":"orderbook_delta","sid":1,"seq":27,"msg":{"market_ticker":"KXFEDDECISION-26SEP-H25","market_id":"749202d4-2a9a-4c24-b73a-116af982e245","price_dollars":"0.1400","delta_fp":"141.00","side":"no","ts":"2026-09-11T15:33:59.726045Z","ts_ms":1789140839726}}
{"type":"orderbook_delta","sid":1,"seq":28,"msg":{"market_ticker":"KXFEDDECISION-26SEP-H25","market_id":"749202d4-2a9a-4c24-b73a-116af982e245","price_dollars":"0.8000","delta_fp":"-200.00","side":"yes","ts":"2026-09-11T15:33:59.734083Z","ts_ms":1789140839734}}
{"type":"orderbook_delta","sid":1,"seq":29,"msg":{"market_ticker":"KXFEDDECISION-26SEP-H25","market_id":"749202d4-2a9a-4c24-b73a-116af982e245","price_dollars":"0.8000","delta_fp":"-946.95","side":"yes","ts":"2026-09-11T15:34:06.803657Z","ts_ms":1789140846803}}
{"type":"orderbook_delta","sid":1,"seq":30,"msg":{"market_ticker":"KXFEDDECISION-26SEP-H25","market_id":"749202d4-2a9a-4c24-b73a-116af982e245","price_dollars":"0.1400","delta_fp":"-141.00","side":"no","ts":"2026-09-11T15:34:06.817292Z","ts_ms":1789140846817}}
{"type":"orderbook_delta","sid":1,"seq":31,"msg":{"market_ticker":"KXFEDDECISION-26SEP-H25","market_id":"749202d4-2a9a-4c24-b73a-116af982e245","price_dollars":"0.7900","delta_fp":"200.00","side":"yes","ts":"2026-09-11T15:34:06.822616Z","ts_ms":1789140846822}}
{"type":"orderbook_delta","sid":1,"seq":32,"msg":{"market_ticker":"KXFEDDECISION-26SEP-H25","market_id":"749202d4-2a9a-4c24-b73a-116af982e245","price_dollars":"0.1500","delta_fp":"141.00","side":"no","ts":"2026-09-11T15:34:06.834828Z","ts_ms":1789140846834}}
{"type":"orderbook_delta","sid":1,"seq":33,"msg":{"market_ticker":"KXFEDDECISION-26SEP-H25","market_id":"749202d4-2a9a-4c24-b73a-116af982e245","price_dollars":"0.1900","delta_fp":"-12.18","side":"no","ts":"2026-09-11T15:34:15.506495Z","ts_ms":1789140855506}}
{"type":"orderbook_delta","sid":1,"seq":34,"msg":{"market_ticker":"KXFEDDECISION-26SEP-H25","market_id":"749202d4-2a9a-4c24-b73a-116af982e245","price_dollars":"0.1800","delta_fp":"-2.00","side":"no","ts":"2026-09-11T15:34:15.527073Z","ts_ms":1789140855527}}
{"type":"orderbook_delta","sid":1,"seq":35,"msg":{"market_ticker":"KXFEDDECISION-26SEP-H25","market_id":"749202d4-2a9a-4c24-b73a-116af982e245","price_dollars":"0.8000","delta_fp":"-14673.00","side":"yes","ts":"2026-09-11T15:34:38.335107Z","ts_ms":1789140878335}}
{"type":"orderbook_delta","sid":1,"seq":36,"msg":{"market_ticker":"KXFEDDECISION-26SEP-H25","market_id":"749202d4-2a9a-4c24-b73a-116af982e245","price_dollars":"0.7800","delta_fp":"-1822.00","side":"yes","ts":"2026-09-11T15:34:38.341651Z","ts_ms":1789140878341}}
{"type":"orderbook_delta","sid":1,"seq":37,"msg":{"market_ticker":"KXFEDDECISION-26SEP-H25","market_id":"749202d4-2a9a-4c24-b73a-116af982e245","price_dollars":"0.1400","delta_fp":"11075.00","side":"no","ts":"2026-09-11T15:35:03.91739Z","ts_ms":1789140903917}}
{"type":"orderbook_delta","sid":1,"seq":38,"msg":{"market_ticker":"KXFEDDECISION-26SEP-H25","market_id":"749202d4-2a9a-4c24-b73a-116af982e245","price_dollars":"0.1900","delta_fp":"25000.00","side":"no","ts":"2026-09-11T15:35:14.785633Z","ts_ms":1789140914785}}
{"type":"orderbook_delta","sid":1,"seq":39,"msg":{"market_ticker":"KXFEDDECISION-26SEP-H25","market_id":"749202d4-2a9a-4c24-b73a-116af982e245","price_dollars":"0.8000","delta_fp":"-4000.00","side":"yes","ts":"2026-09-11T15:35:14.792987Z","ts_ms":1789140914792}}
{"type":"orderbook_delta","sid":1,"seq":40,"msg":{"market_ticker":"KXFEDDECISION-26SEP-H25","market_id":"749202d4-2a9a-4c24-b73a-116af982e245","price_dollars":"0.7900","delta_fp":"4000.00","side":"yes","ts":"2026-09-11T15:35:14.792987Z","ts_ms":1789140914792}}
{"type":"orderbook_delta","sid":1,"seq":41,"msg":{"market_ticker":"KXFEDDECISION-26SEP-H25","market_id":"749202d4-2a9a-4c24-b73a-116af982e245","price_dollars":"0.1800","delta_fp":"1019.00","side":"no","ts":"2026-09-11T15:35:14.803542Z","ts_ms":1789140914803}}
{"type":"orderbook_delta","sid":1,"seq":42,"msg":{"market_ticker":"KXFEDDECISION-26SEP-H25","market_id":"749202d4-2a9a-4c24-b73a-116af982e245","price_dollars":"0.8000","delta_fp":"-39.00","side":"yes","ts":"2026-09-11T15:35:24.773783Z","ts_ms":1789140924773}}
{"type":"orderbook_delta","sid":1,"seq":43,"msg":{"market_ticker":"KXFEDDECISION-26SEP-H25","market_id":"749202d4-2a9a-4c24-b73a-116af982e245","price_dollars":"0.8000","delta_fp":"3500.00","side":"yes","ts":"2026-09-11T15:35:25.704213Z","ts_ms":1789140925704}}
{"type":"orderbook_delta","sid":1,"seq":44,"msg":{"market_ticker":"KXFEDDECISION-26SEP-H25","market_id":"749202d4-2a9a-4c24-b73a-116af982e245","price_dollars":"0.8000","delta_fp":"-18779.64","side":"yes","ts":"2026-09-11T15:35:32.958188Z","ts_ms":1789140932958}}
{"type":"orderbook_delta","sid":1,"seq":45,"msg":{"market_ticker":"KXFEDDECISION-26SEP-H25","market_id":"749202d4-2a9a-4c24-b73a-116af982e245","price_dollars":"0.8000","delta_fp":"-6220.36","side":"yes","ts":"2026-09-11T15:35:32.958188Z","ts_ms":1789140932958}}
{"type":"orderbook_delta","sid":1,"seq":46,"msg":{"market_ticker":"KXFEDDECISION-26SEP-H25","market_id":"749202d4-2a9a-4c24-b73a-116af982e245","price_dollars":"0.8000","delta_fp":"-3731.64","side":"yes","ts":"2026-09-11T15:35:33.088969Z","ts_ms":1789140933088}}
{"type":"orderbook_delta","sid":1,"seq":47,"msg":{"market_ticker":"KXFEDDECISION-26SEP-H25","market_id":"749202d4-2a9a-4c24-b73a-116af982e245","price_dollars":"0.7800","delta_fp":"-5785.00","side":"yes","ts":"2026-09-11T15:35:33.09019Z","ts_ms":1789140933090}}
{"type":"orderbook_delta","sid":1,"seq":48,"msg":{"market_ticker":"KXFEDDECISION-26SEP-H25","market_id":"749202d4-2a9a-4c24-b73a-116af982e245","price_dollars":"0.1800","delta_fp":"2.00","side":"no","ts":"2026-09-11T15:35:35.022504Z","ts_ms":1789140935022}}
{"type":"orderbook_delta","sid":1,"seq":49,"msg":{"market_ticker":"KXFEDDECISION-26SEP-H25","market_id":"749202d4-2a9a-4c24-b73a-116af982e245","price_dollars":"0.1800","delta_fp":"-2.00","side":"no","ts":"2026-09-11T15:35:42.051421Z","ts_ms":1789140942051}}
{"type":"orderbook_delta","sid":1,"seq":50,"msg":{"market_ticker":"KXFEDDECISION-26SEP-H25","market_id":"749202d4-2a9a-4c24-b73a-116af982e245","price_dollars":"0.7900","delta_fp":"50000.00","side":"yes","ts":"2026-09-11T15:36:07.3712Z","ts_ms":1789140967371}}
{"type":"orderbook_delta","sid":1,"seq":51,"msg":{"market_ticker":"KXFEDDECISION-26SEP-H25","market_id":"749202d4-2a9a-4c24-b73a-116af982e245","price_dollars":"0.7800","delta_fp":"1860.00","side":"yes","ts":"2026-09-11T15:36:17.407998Z","ts_ms":1789140977407}}
{"type":"orderbook_delta","sid":1,"seq":52,"msg":{"market_ticker":"KXFEDDECISION-26SEP-H25","market_id":"749202d4-2a9a-4c24-b73a-116af982e245","price_dollars":"0.8000","delta_fp":"-454.50","side":"yes","ts":"2026-09-11T15:36:25.450404Z","ts_ms":1789140985450}}
{"type":"orderbook_delta","sid":1,"seq":53,"msg":{"market_ticker":"KXFEDDECISION-26SEP-H25","market_id":"749202d4-2a9a-4c24-b73a-116af982e245","price_dollars":"0.7800","delta_fp":"-423.00","side":"yes","ts":"2026-09-11T15:36:25.579595Z","ts_ms":1789140985579}}
{"type":"orderbook_delta","sid":1,"seq":54,"msg":{"market_ticker":"KXFEDDECISION-26SEP-H25","market_id":"749202d4-2a9a-4c24-b73a-116af982e245","price_dollars":"0.1900","delta_fp":"260.00","side":"no","ts":"2026-09-11T15:36:26.075579Z","ts_ms":1789140986075}}
{"type":"orderbook_delta","sid":1,"seq":55,"msg":{"market_ticker":"KXFEDDECISION-26SEP-H25","market_id":"749202d4-2a9a-4c24-b73a-116af982e245","price_dollars":"0.1900","delta_fp":"-121.83","side":"no","ts":"2026-09-11T15:36:48.656994Z","ts_ms":1789141008656}}
{"type":"orderbook_delta","sid":1,"seq":56,"msg":{"market_ticker":"KXFEDDECISION-26SEP-H25","market_id":"749202d4-2a9a-4c24-b73a-116af982e245","price_dollars":"0.1900","delta_fp":"3500.00","side":"no","ts":"2026-09-11T15:37:15.487063Z","ts_ms":1789141035487}}
{"type":"orderbook_delta","sid":1,"seq":57,"msg":{"market_ticker":"KXFEDDECISION-26SEP-H25","market_id":"749202d4-2a9a-4c24-b73a-116af982e245","price_dollars":"0.1900","delta_fp":"1581.00","side":"no","ts":"2026-09-11T15:37:15.503701Z","ts_ms":1789141035503}}
{"type":"orderbook_delta","sid":1,"seq":58,"msg":{"market_ticker":"KXFEDDECISION-26SEP-H25","market_id":"749202d4-2a9a-4c24-b73a-116af982e245","price_dollars":"0.1800","delta_fp":"-562.00","side":"no","ts":"2026-09-11T15:37:15.50412Z","ts_ms":1789141035504}}
{"type":"orderbook_delta","sid":1,"seq":59,"msg":{"market_ticker":"KXFEDDECISION-26SEP-H25","market_id":"749202d4-2a9a-4c24-b73a-116af982e245","price_dollars":"0.1800","delta_fp":"-1019.00","side":"no","ts":"2026-09-11T15:37:15.504521Z","ts_ms":1789141035504}}
{"type":"orderbook_delta","sid":1,"seq":60,"msg":{"market_ticker":"KXFEDDECISION-26SEP-H25","market_id":"749202d4-2a9a-4c24-b73a-116af982e245","price_dollars":"0.7900","delta_fp":"-200.00","side":"yes","ts":"2026-09-11T15:37:18.973943Z","ts_ms":1789141038973}}
{"type":"orderbook_delta","sid":1,"seq":61,"msg":{"market_ticker":"KXFEDDECISION-26SEP-H25","market_id":"749202d4-2a9a-4c24-b73a-116af982e245","price_dollars":"0.1500","delta_fp":"-141.00","side":"no","ts":"2026-09-11T15:37:18.982574Z","ts_ms":1789141038982}}
{"type":"orderbook_delta","sid":1,"seq":62,"msg":{"market_ticker":"KXFEDDECISION-26SEP-H25","market_id":"749202d4-2a9a-4c24-b73a-116af982e245","price_dollars":"0.8000","delta_fp":"200.00","side":"yes","ts":"2026-09-11T15:37:18.992986Z","ts_ms":1789141038992}}
{"type":"orderbook_delta","sid":1,"seq":63,"msg":{"market_ticker":"KXFEDDECISION-26SEP-H25","market_id":"749202d4-2a9a-4c24-b73a-116af982e245","price_dollars":"0.1400","delta_fp":"141.00","side":"no","ts":"2026-09-11T15:37:19.015184Z","ts_ms":1789141039015}}
{"type":"orderbook_delta","sid":1,"seq":64,"msg":{"market_ticker":"KXFEDDECISION-26SEP-H25","market_id":"749202d4-2a9a-4c24-b73a-116af982e245","price_dollars":"0.8000","delta_fp":"-1333.50","side":"yes","ts":"2026-09-11T15:37:34.410143Z","ts_ms":1789141054410}}
{"type":"orderbook_delta","sid":1,"seq":65,"msg":{"market_ticker":"KXFEDDECISION-26SEP-H25","market_id":"749202d4-2a9a-4c24-b73a-116af982e245","price_dollars":"0.7800","delta_fp":"-1437.00","side":"yes","ts":"2026-09-11T15:37:34.412654Z","ts_ms":1789141054412}}
{"type":"orderbook_delta","sid":1,"seq":66,"msg":{"market_ticker":"KXFEDDECISION-26SEP-H25","market_id":"749202d4-2a9a-4c24-b73a-116af982e245","price_dollars":"0.7800","delta_fp":"-7863.00","side":"yes","ts":"2026-09-11T15:37:34.41624Z","ts_ms":1789141054416}}
{"type":"orderbook_delta","sid":1,"seq":67,"msg":{"market_ticker":"KXFEDDECISION-26SEP-H25","market_id":"749202d4-2a9a-4c24-b73a-116af982e245","price_dollars":"0.1700","delta_fp":"-4000.00","side":"no","ts":"2026-09-11T15:37:39.325352Z","ts_ms":1789141059325}}
{"type":"orderbook_delta","sid":1,"seq":68,"msg":{"market_ticker":"KXFEDDECISION-26SEP-H25","market_id":"749202d4-2a9a-4c24-b73a-116af982e245","price_dollars":"0.1600","delta_fp":"-1500.00","side":"no","ts":"2026-09-11T15:37:41.000091Z","ts_ms":1789141061000}}
{"type":"orderbook_delta","sid":1,"seq":69,"msg":{"market_ticker":"KXFEDDECISION-26SEP-H25","market_id":"749202d4-2a9a-4c24-b73a-116af982e245","price_dollars":"0.7800","delta_fp":"4650.00","side":"yes","ts":"2026-09-11T15:37:41.95283Z","ts_ms":1789141061952}}
{"type":"orderbook_delta","sid":1,"seq":70,"msg":{"market_ticker":"KXFEDDECISION-26SEP-H25","market_id":"749202d4-2a9a-4c24-b73a-116af982e245","price_dollars":"0.1900","delta_fp":"-121.83","side":"no","ts":"2026-09-11T15:38:01.850984Z","ts_ms":1789141081850}}
{"type":"orderbook_delta","sid":1,"seq":71,"msg":{"market_ticker":"KXFEDDECISION-26SEP-H25","market_id":"749202d4-2a9a-4c24-b73a-116af982e245","price_dollars":"0.0800","delta_fp":"121.83","side":"no","ts":"2026-09-11T15:38:12.288775Z","ts_ms":1789141092288}}
{"type":"orderbook_delta","sid":1,"seq":72,"msg":{"market_ticker":"KXFEDDECISION-26SEP-H25","market_id":"749202d4-2a9a-4c24-b73a-116af982e245","price_dollars":"0.7800","delta_fp":"-245.00","side":"yes","ts":"2026-09-11T15:38:19.303562Z","ts_ms":1789141099303}}
{"type":"orderbook_delta","sid":1,"seq":73,"msg":{"market_ticker":"KXFEDDECISION-26SEP-H25","market_id":"749202d4-2a9a-4c24-b73a-116af982e245","price_dollars":"0.7800","delta_fp":"1860.00","side":"yes","ts":"2026-09-11T15:38:56.894967Z","ts_ms":1789141136894}}
{"type":"orderbook_delta","sid":1,"seq":74,"msg":{"market_ticker":"KXFEDDECISION-26SEP-H25","market_id":"749202d4-2a9a-4c24-b73a-116af982e245","price_dollars":"0.8000","delta_fp":"-100.00","side":"yes","ts":"2026-09-11T15:38:57.144177Z","ts_ms":1789141137144}}
{"type":"orderbook_delta","sid":1,"seq":75,"msg":{"market_ticker":"KXFEDDECISION-26SEP-H25","market_id":"749202d4-2a9a-4c24-b73a-116af982e245","price_dollars":"0.8000","delta_fp":"-3500.00","side":"yes","ts":"2026-09-11T15:39:06.000582Z","ts_ms":1789141146000}}
{"type":"orderbook_delta","sid":1,"seq":76,"msg":{"market_ticker":"KXFEDDECISION-26SEP-H25","market_id":"749202d4-2a9a-4c24-b73a-116af982e245","price_dollars":"0.1800","delta_fp":"2.00","side":"no","ts":"2026-09-11T15:39:06.078166Z","ts_ms":1789141146078}}
{"type":"orderbook_delta","sid":1,"seq":77,"msg":{"market_ticker":"KXFEDDECISION-26SEP-H25","market_id":"749202d4-2a9a-4c24-b73a-116af982e245","price_dollars":"0.1800","delta_fp":"-2.00","side":"no","ts":"2026-09-11T15:39:07.017673Z","ts_ms":1789141147017}}
{"type":"orderbook_delta","sid":1,"seq":78,"msg":{"market_ticker":"KXFEDDECISION-26SEP-H25","market_id":"749202d4-2a9a-4c24-b73a-116af982e245","price_dollars":"0.8000","delta_fp":"-100.00","side":"yes","ts":"2026-09-11T15:39:10.191816Z","ts_ms":1789141150191}}
{"type":"orderbook_delta","sid":1,"seq":79,"msg":{"market_ticker":"KXFEDDECISION-26SEP-H25","market_id":"749202d4-2a9a-4c24-b73a-116af982e245","price_dollars":"0.8000","delta_fp":"-200.00","side":"yes","ts":"2026-09-11T15:39:10.216177Z","ts_ms":1789141150216}}
{"type":"orderbook_delta","sid":1,"seq":80,"msg":{"market_ticker":"KXFEDDECISION-26SEP-H25","market_id":"749202d4-2a9a-4c24-b73a-116af982e245","price_dollars":"0.1400","delta_fp":"-141.00","side":"no","ts":"2026-09-11T15:39:10.248285Z","ts_ms":1789141150248}}
{"type":"orderbook_delta","sid":1,"seq":81,"msg":{"market_ticker":"KXFEDDECISION-26SEP-H25","market_id":"749202d4-2a9a-4c24-b73a-116af982e245","price_dollars":"0.7900","delta_fp":"200.00","side":"yes","ts":"2026-09-11T15:39:10.263944Z","ts_ms":1789141150263}}
{"type":"orderbook_delta","sid":1,"seq":82,"msg":{"market_ticker":"KXFEDDECISION-26SEP-H25","market_id":"749202d4-2a9a-4c24-b73a-116af982e245","price_dollars":"0.1500","delta_fp":"141.00","side":"no","ts":"2026-09-11T15:39:10.268513Z","ts_ms":1789141150268}}
{"type":"orderbook_delta","sid":1,"seq":83,"msg":{"market_ticker":"KXFEDDECISION-26SEP-H25","market_id":"749202d4-2a9a-4c24-b73a-116af982e245","price_dollars":"0.1800","delta_fp":"2.00","side":"no","ts":"2026-09-11T15:39:13.028653Z","ts_ms":1789141153028}}
{"type":"orderbook_delta","sid":1,"seq":84,"msg":{"market_ticker":"KXFEDDECISION-26SEP-H25","market_id":"749202d4-2a9a-4c24-b73a-116af982e245","price_dollars":"0.1800","delta_fp":"-2.00","side":"no","ts":"2026-09-11T15:39:20.019106Z","ts_ms":1789141160019}}
{"type":"orderbook_delta","sid":1,"seq":85,"msg":{"market_ticker":"KXFEDDECISION-26SEP-H25","market_id":"749202d4-2a9a-4c24-b73a-116af982e245","price_dollars":"0.1900","delta_fp":"-180.71","side":"no","ts":"2026-09-11T15:39:24.65069Z","ts_ms":1789141164650}}
{"type":"orderbook_delta","sid":1,"seq":86,"msg":{"market_ticker":"KXFEDDECISION-26SEP-H25","market_id":"749202d4-2a9a-4c24-b73a-116af982e245","price_dollars":"0.7900","delta_fp":"-200.00","side":"yes","ts":"2026-09-11T15:39:24.677354Z","ts_ms":1789141164677}}
{"type":"orderbook_delta","sid":1,"seq":87,"msg":{"market_ticker":"KXFEDDECISION-26SEP-H25","market_id":"749202d4-2a9a-4c24-b73a-116af982e245","price_dollars":"0.1500","delta_fp":"-141.00","side":"no","ts":"2026-09-11T15:39:24.682494Z","ts_ms":1789141164682}}
{"type":"orderbook_delta","sid":1,"seq":88,"msg":{"market_ticker":"KXFEDDECISION-26SEP-H25","market_id":"749202d4-2a9a-4c24-b73a-116af982e245","price_dollars":"0.8000","delta_fp":"200.00","side":"yes","ts":"2026-09-11T15:39:24.69566Z","ts_ms":1789141164695}}
{"type":"orderbook_delta","sid":1,"seq":89,"msg":{"market_ticker":"KXFEDDECISION-26SEP-H25","market_id":"749202d4-2a9a-4c24-b73a-116af982e245","price_dollars":"0.1400","delta_fp":"141.00","side":"no","ts":"2026-09-11T15:39:24.702607Z","ts_ms":1789141164702}}
{"type":"orderbook_delta","sid":1,"seq":90,"msg":{"market_ticker":"KXFEDDECISION-26SEP-H25","market_id":"749202d4-2a9a-4c24-b73a-116af982e245","price_dollars":"0.8000","delta_fp":"-946.95","side":"yes","ts":"2026-09-11T15:39:29.128747Z","ts_ms":1789141169128}}
{"type":"orderbook_delta","sid":1,"seq":91,"msg":{"market_ticker":"KXFEDDECISION-26SEP-H25","market_id":"749202d4-2a9a-4c24-b73a-116af982e245","price_dollars":"0.8000","delta_fp":"-200.00","side":"yes","ts":"2026-09-11T15:39:29.154209Z","ts_ms":1789141169154}}
{"type":"orderbook_delta","sid":1,"seq":92,"msg":{"market_ticker":"KXFEDDECISION-26SEP-H25","market_id":"749202d4-2a9a-4c24-b73a-116af982e245","price_dollars":"0.1400","delta_fp":"-141.00","side":"no","ts":"2026-09-11T15:39:29.16447Z","ts_ms":1789141169164}}
{"type":"orderbook_delta","sid":1,"seq":93,"msg":{"market_ticker":"KXFEDDECISION-26SEP-H25","market_id":"749202d4-2a9a-4c24-b73a-116af982e245","price_dollars":"0.7900","delta_fp":"200.00","side":"yes","ts":"2026-09-11T15:39:29.167658Z","ts_ms":1789141169167}}
{"type":"orderbook_delta","sid":1,"seq":94,"msg":{"market_ticker":"KXFEDDECISION-26SEP-H25","market_id":"749202d4-2a9a-4c24-b73a-116af982e245","price_dollars":"0.1500","delta_fp":"141.00","side":"no","ts":"2026-09-11T15:39:29.177457Z","ts_ms":1789141169177}}
{"type":"orderbook_delta","sid":1,"seq":95,"msg":{"market_ticker":"KXFEDDECISION-26SEP-H25","market_id":"749202d4-2a9a-4c24-b73a-116af982e245","price_dollars":"0.7800","delta_fp":"-1066.00","side":"yes","ts":"2026-09-11T15:39:29.330181Z","ts_ms":1789141169330}}
{"type":"orderbook_delta","sid":1,"seq":96,"msg":{"market_ticker":"KXFEDDECISION-26SEP-H25","market_id":"749202d4-2a9a-4c24-b73a-116af982e245","price_dollars":"0.7800","delta_fp":"-474.00","side":"yes","ts":"2026-09-11T15:39:46.355979Z","ts_ms":1789141186355}}
{"type":"orderbook_delta","sid":1,"seq":97,"msg":{"market_ticker":"KXFEDDECISION-26SEP-H25","market_id":"749202d4-2a9a-4c24-b73a-116af982e245","price_dollars":"0.1900","delta_fp":"-39.98","side":"no","ts":"2026-09-11T15:40:02.631532Z","ts_ms":1789141202631}}
{"type":"orderbook_delta","sid":1,"seq":98,"msg":{"market_ticker":"KXFEDDECISION-26SEP-H25","market_id":"749202d4-2a9a-4c24-b73a-116af982e245","price_dollars":"0.1900","delta_fp":"-30.10","side":"no","ts":"2026-09-11T15:40:07.475849Z","ts_ms":1789141207475}}
{"type":"orderbook_delta","sid":1,"seq":99,"msg":{"market_ticker":"KXFEDDECISION-26SEP-H25","market_id":"749202d4-2a9a-4c24-b73a-116af982e245","price_dollars":"0.0100","delta_fp":"39.98","side":"no","ts":"2026-09-11T15:40:14.58035Z","ts_ms":1789141214580}}
{"type":"orderbook_delta","sid":1,"seq":100,"msg":{"market_ticker":"KXFEDDECISION-26SEP-H25","market_id":"749202d4-2a9a-4c24-b73a-116af982e245","price_dollars":"0.1900","delta_fp":"-1.21","side":"no","ts":"2026-09-11T15:40:30.830901Z","ts_ms":1789141230830}}
{"type":"orderbook_delta","sid":1,"seq":101,"msg":{"market_ticker":"KXFEDDECISION-26SEP-H25","market_id":"749202d4-2a9a-4c24-b73a-116af982e245","price_dollars":"0.7800","delta_fp":"-320.00","side":"yes","ts":"2026-09-11T15:40:32.277934Z","ts_ms":1789141232277}}
{"type":"orderbook_delta","sid":1,"seq":102,"msg":{"market_ticker":"KXFEDDECISION-26SEP-H25","market_id":"749202d4-2a9a-4c24-b73a-116af982e245","price_dollars":"0.7800","delta_fp":"-238.00","side":"yes","ts":"2026-09-11T15:40:32.288164Z","ts_ms":1789141232288}}
{"type":"orderbook_delta","sid":1,"seq":103,"msg":{"market_ticker":"KXFEDDECISION-26SEP-H25","market_id":"749202d4-2a9a-4c24-b73a-116af982e245","price_dollars":"0.0100","delta_fp":"1.21","side":"no","ts":"2026-09-11T15:40:34.715566Z","ts_ms":1789141234715}}
{"type":"orderbook_delta","sid":1,"seq":104,"msg":{"market_ticker":"KXFEDDECISION-26SEP-H25","market_id":"749202d4-2a9a-4c24-b73a-116af982e245","price_dollars":"0.1900","delta_fp":"-12.18","side":"no","ts":"2026-09-11T15:40:37.009728Z","ts_ms":1789141237009}}
{"type":"orderbook_delta","sid":1,"seq":105,"msg":{"market_ticker":"KXFEDDECISION-26SEP-H25","market_id":"749202d4-2a9a-4c24-b73a-116af982e245","price_dollars":"0.7900","delta_fp":"-200.00","side":"yes","ts":"2026-09-11T15:41:22.2801Z","ts_ms":1789141282280}}
{"type":"orderbook_delta","sid":1,"seq":106,"msg":{"market_ticker":"KXFEDDECISION-26SEP-H25","market_id":"749202d4-2a9a-4c24-b73a-116af982e245","price_dollars":"0.1500","delta_fp":"-141.00","side":"no","ts":"2026-09-11T15:41:22.286584Z","ts_ms":1789141282286}}
{"type":"orderbook_delta","sid":1,"seq":107,"msg":{"market_ticker":"KXFEDDECISION-26SEP-H25","market_id":"749202d4-2a9a-4c24-b73a-116af982e245","price_dollars":"0.8000","delta_fp":"200.00","side":"yes","ts":"2026-09-11T15:41:22.335946Z","ts_ms":1789141282335}}
{"type":"orderbook_delta","sid":1,"seq":108,"msg":{"market_ticker":"KXFEDDECISION-26SEP-H25","market_id":"749202d4-2a9a-4c24-b73a-116af982e245","price_dollars":"0.1400","delta_fp":"141.00","side":"no","ts":"2026-09-11T15:41:22.347084Z","ts_ms":1789141282347}}
{"type":"orderbook_delta","sid":1,"seq":109,"msg":{"market_ticker":"KXFEDDECISION-26SEP-H25","market_id":"749202d4-2a9a-4c24-b73a-116af982e245","price_dollars":"0.8000","delta_fp":"-200.00","side":"yes","ts":"2026-09-11T15:41:23.006904Z","ts_ms":1789141283006}}
{"type":"orderbook_delta","sid":1,"seq":110,"msg":{"market_ticker":"KXFEDDECISION-26SEP-H25","market_id":"749202d4-2a9a-4c24-b73a-116af982e245","price_dollars":"0.1400","delta_fp":"-141.00","side":"no","ts":"2026-09-11T15:41:23.013219Z","ts_ms":1789141283013}}
{"type":"orderbook_delta","sid":1,"seq":111,"msg":{"market_ticker":"KXFEDDECISION-26SEP-H25","market_id":"749202d4-2a9a-4c24-b73a-116af982e245","price_dollars":"0.7900","delta_fp":"200.00","side":"yes","ts":"2026-09-11T15:41:23.025285Z","ts_ms":1789141283025}}
{"type":"orderbook_delta","sid":1,"seq":112,"msg":{"market_ticker":"KXFEDDECISION-26SEP-H25","market_id":"749202d4-2a9a-4c24-b73a-116af982e245","price_dollars":"0.1500","delta_fp":"141.00","side":"no","ts":"2026-09-11T15:41:23.0375Z","ts_ms":1789141283037}}
{"type":"orderbook_delta","sid":1,"seq":113,"msg":{"market_ticker":"KXFEDDECISION-26SEP-H25","market_id":"749202d4-2a9a-4c24-b73a-116af982e245","price_dollars":"0.0100","delta_fp":"12.18","side":"no","ts":"2026-09-11T15:41:24.63991Z","ts_ms":1789141284639}}
{"type":"orderbook_delta","sid":1,"seq":114,"msg":{"market_ticker":"KXFEDDECISION-26SEP-H25","market_id":"749202d4-2a9a-4c24-b73a-116af982e245","price_dollars":"0.1900","delta_fp":"-1.21","side":"no","ts":"2026-09-11T15:41:31.628283Z","ts_ms":1789141291628}}
{"type":"orderbook_delta","sid":1,"seq":115,"msg":{"market_ticker":"KXFEDDECISION-26SEP-H25","market_id":"749202d4-2a9a-4c24-b73a-116af982e245","price_dollars":"0.5100","delta_fp":"100000.00","side":"yes","ts":"2026-09-11T15:41:38.589608Z","ts_ms":1789141298589}}
{"type":"orderbook_delta","sid":1,"seq":116,"msg":{"market_ticker":"KXFEDDECISION-26SEP-H25","market_id":"749202d4-2a9a-4c24-b73a-116af982e245","price_dollars":"0.1900","delta_fp":"-1.21","side":"no","ts":"2026-09-11T15:41:59.536607Z","ts_ms":1789141319536}}
{"type":"orderbook_delta","sid":1,"seq":117,"msg":{"market_ticker":"KXFEDDECISION-26SEP-H25","market_id":"749202d4-2a9a-4c24-b73a-116af982e245","price_dollars":"0.5000","delta_fp":"-8137.00","side":"yes","ts":"2026-09-11T15:41:59.626537Z","ts_ms":1789141319626}}
{"type":"orderbook_delta","sid":1,"seq":118,"msg":{"market_ticker":"KXFEDDECISION-26SEP-H25","market_id":"749202d4-2a9a-4c24-b73a-116af982e245","price_dollars":"0.5200","delta_fp":"23846.00","side":"yes","ts":"2026-09-11T15:41:59.651664Z","ts_ms":1789141319651}}
{"type":"orderbook_delta","sid":1,"seq":119,"msg":{"market_ticker":"KXFEDDECISION-26SEP-H25","market_id":"749202d4-2a9a-4c24-b73a-116af982e245","price_dollars":"0.7900","delta_fp":"-200.00","side":"yes","ts":"2026-09-11T15:42:04.616368Z","ts_ms":1789141324616}}
{"type":"orderbook_delta","sid":1,"seq":120,"msg":{"market_ticker":"KXFEDDECISION-26SEP-H25","market_id":"749202d4-2a9a-4c24-b73a-116af982e245","price_dollars":"0.1500","delta_fp":"-141.00","side":"no","ts":"2026-09-11T15:42:04.622863Z","ts_ms":1789141324622}}
{"type":"orderbook_delta","sid":1,"seq":121,"msg":{"market_ticker":"KXFEDDECISION-26SEP-H25","market_id":"749202d4-2a9a-4c24-b73a-116af982e245","price_dollars":"0.8000","delta_fp":"200.00","side":"yes","ts":"2026-09-11T15:42:04.656969Z","ts_ms":1789141324656}}
{"type":"orderbook_delta","sid":1,"seq":122,"msg":{"market_ticker":"KXFEDDECISION-26SEP-H25","market_id":"749202d4-2a9a-4c24-b73a-116af982e245","price_dollars":"0.1400","delta_fp":"141.00","side":"no","ts":"2026-09-11T15:42:04.663526Z","ts_ms":1789141324663}}
{"type":"orderbook_delta","sid":1,"seq":123,"msg":{"market_ticker":"KXFEDDECISION-26SEP-H25","market_id":"749202d4-2a9a-4c24-b73a-116af982e245","price_dollars":"0.8000","delta_fp":"-200.00","side":"yes","ts":"2026-09-11T15:42:07.231501Z","ts_ms":1789141327231}}
{"type":"orderbook_delta","sid":1,"seq":124,"msg":{"market_ticker":"KXFEDDECISION-26SEP-H25","market_id":"749202d4-2a9a-4c24-b73a-116af982e245","price_dollars":"0.1400","delta_fp":"-141.00","side":"no","ts":"2026-09-11T15:42:07.23806Z","ts_ms":1789141327238}}
{"type":"orderbook_delta","sid":1,"seq":125,"msg":{"market_ticker":"KXFEDDECISION-26SEP-H25","market_id":"749202d4-2a9a-4c24-b73a-116af982e245","price_dollars":"0.7900","delta_fp":"200.00","side":"yes","ts":"2026-09-11T15:42:07.249141Z","ts_ms":1789141327249}}
{"type":"orderbook_delta","sid":1,"seq":126,"msg":{"market_ticker":"KXFEDDECISION-26SEP-H25","market_id":"749202d4-2a9a-4c24-b73a-116af982e245","price_dollars":"0.1500","delta_fp":"141.00","side":"no","ts":"2026-09-11T15:42:07.259022Z","ts_ms":1789141327259}}
{"type":"orderbook_delta","sid":1,"seq":127,"msg":{"market_ticker":"KXFEDDECISION-26SEP-H25","market_id":"749202d4-2a9a-4c24-b73a-116af982e245","price_dollars":"0.1400","delta_fp":"-4504.00","side":"no","ts":"2026-09-11T15:42:09.354977Z","ts_ms":1789141329354}}
{"type":"orderbook_delta","sid":1,"seq":128,"msg":{"market_ticker":"KXFEDDECISION-26SEP-H25","market_id":"749202d4-2a9a-4c24-b73a-116af982e245","price_dollars":"0.1500","delta_fp":"-632.00","side":"no","ts":"2026-09-11T15:42:10.079149Z","ts_ms":1789141330079}}
{"type":"orderbook_delta","sid":1,"seq":129,"msg":{"market_ticker":"KXFEDDECISION-26SEP-H25","market_id":"749202d4-2a9a-4c24-b73a-116af982e245","price_dollars":"0.1400","delta_fp":"-568.00","side":"no","ts":"2026-09-11T15:42:11.820951Z","ts_ms":1789141331820}}
{"type":"orderbook_delta","sid":1,"seq":130,"msg":{"market_ticker":"KXFEDDECISION-26SEP-H25","market_id":"749202d4-2a9a-4c24-b73a-116af982e245","price_dollars":"0.1800","delta_fp":"2500.00","side":"no","ts":"2026-09-11T15:42:23.479057Z","ts_ms":1789141343479}}
{"type":"orderbook_delta","sid":1,"seq":131,"msg":{"market_ticker":"KXFEDDECISION-26SEP-H25","market_id":"749202d4-2a9a-4c24-b73a-116af982e245","price_dollars":"0.0800","delta_fp":"1.21","side":"no","ts":"2026-09-11T15:42:23.826607Z","ts_ms":1789141343826}}
{"type":"orderbook_delta","sid":1,"seq":132,"msg":{"market_ticker":"KXFEDDECISION-26SEP-H25","market_id":"749202d4-2a9a-4c24-b73a-116af982e245","price_dollars":"0.7800","delta_fp":"9360.00","side":"yes","ts":"2026-09-11T15:42:53.576623Z","ts_ms":1789141373576}}
{"type":"orderbook_delta","sid":1,"seq":133,"msg":{"market_ticker":"KXFEDDECISION-26SEP-H25","market_id":"749202d4-2a9a-4c24-b73a-116af982e245","price_dollars":"0.0100","delta_fp":"-12.18","side":"no","ts":"2026-09-11T15:43:06.256698Z","ts_ms":1789141386256}}
{"type":"orderbook_delta","sid":1,"seq":134,"msg":{"market_ticker":"KXFEDDECISION-26SEP-H25","market_id":"749202d4-2a9a-4c24-b73a-116af982e245","price_dollars":"0.8000","delta_fp":"-12.18","side":"yes","ts":"2026-09-11T15:43:06.265862Z","ts_ms":1789141386265}}
{"type":"orderbook_delta","sid":1,"seq":135,"msg":{"market_ticker":"KXFEDDECISION-26SEP-H25","market_id":"749202d4-2a9a-4c24-b73a-116af982e245","price_dollars":"0.7800","delta_fp":"-1044.00","side":"yes","ts":"2026-09-11T15:43:06.451557Z","ts_ms":1789141386451}}
{"type":"orderbook_delta","sid":1,"seq":136,"msg":{"market_ticker":"KXFEDDECISION-26SEP-H25","market_id":"749202d4-2a9a-4c24-b73a-116af982e245","price_dollars":"0.1800","delta_fp":"2.00","side":"no","ts":"2026-09-11T15:43:11.16748Z","ts_ms":1789141391167}}
{"type":"orderbook_delta","sid":1,"seq":137,"msg":{"market_ticker":"KXFEDDECISION-26SEP-H25","market_id":"749202d4-2a9a-4c24-b73a-116af982e245","price_dollars":"0.7800","delta_fp":"2893.00","side":"yes","ts":"2026-09-11T15:43:11.303011Z","ts_ms":1789141391303}}
{"type":"orderbook_delta","sid":1,"seq":138,"msg":{"market_ticker":"KXFEDDECISION-26SEP-H25","market_id":"749202d4-2a9a-4c24-b73a-116af982e245","price_dollars":"0.1800","delta_fp":"-2.00","side":"no","ts":"2026-09-11T15:43:16.032184Z","ts_ms":1789141396032}}
{"type":"orderbook_delta","sid":1,"seq":139,"msg":{"market_ticker":"KXFEDDECISION-26SEP-H25","market_id":"749202d4-2a9a-4c24-b73a-116af982e245","price_dollars":"0.7800","delta_fp":"-5005.00","side":"yes","ts":"2026-09-11T15:43:18.786227Z","ts_ms":1789141398786}}
{"type":"orderbook_delta","sid":1,"seq":140,"msg":{"market_ticker":"KXFEDDECISION-26SEP-H25","market_id":"749202d4-2a9a-4c24-b73a-116af982e245","price_dollars":"0.7800","delta_fp":"-2893.00","side":"yes","ts":"2026-09-11T15:43:18.787113Z","ts_ms":1789141398787}}
{"type":"orderbook_delta","sid":1,"seq":141,"msg":{"market_ticker":"KXFEDDECISION-26SEP-H25","market_id":"749202d4-2a9a-4c24-b73a-116af982e245","price_dollars":"0.1400","delta_fp":"-247.00","side":"no","ts":"2026-09-11T15:43:27.346993Z","ts_ms":1789141407346}}
{"type":"orderbook_delta","sid":1,"seq":142,"msg":{"market_ticker":"KXFEDDECISION-26SEP-H25","market_id":"749202d4-2a9a-4c24-b73a-116af982e245","price_dollars":"0.1400","delta_fp":"-1129.00","side":"no","ts":"2026-09-11T15:43:38.330633Z","ts_ms":1789141418330}}
{"type":"orderbook_delta","sid":1,"seq":143,"msg":{"market_ticker":"KXFEDDECISION-26SEP-H25","market_id":"749202d4-2a9a-4c24-b73a-116af982e245","price_dollars":"0.7800","delta_fp":"-1033.00","side":"yes","ts":"2026-09-11T15:43:38.368804Z","ts_ms":1789141418368}}
{"type":"orderbook_delta","sid":1,"seq":144,"msg":{"market_ticker":"KXFEDDECISION-26SEP-H25","market_id":"749202d4-2a9a-4c24-b73a-116af982e245","price_dollars":"0.1500","delta_fp":"-2202.00","side":"no","ts":"2026-09-11T15:43:40.064331Z","ts_ms":1789141420064}}
{"type":"orderbook_delta","sid":1,"seq":145,"msg":{"market_ticker":"KXFEDDECISION-26SEP-H25","market_id":"749202d4-2a9a-4c24-b73a-116af982e245","price_dollars":"0.1500","delta_fp":"-2449.00","side":"no","ts":"2026-09-11T15:43:40.069852Z","ts_ms":1789141420069}}
{"type":"orderbook_delta","sid":1,"seq":146,"msg":{"market_ticker":"KXFEDDECISION-26SEP-H25","market_id":"749202d4-2a9a-4c24-b73a-116af982e245","price_dollars":"0.7900","delta_fp":"-200.00","side":"yes","ts":"2026-09-11T15:43:41.947593Z","ts_ms":1789141421947}}
{"type":"orderbook_delta","sid":1,"seq":147,"msg":{"market_ticker":"KXFEDDECISION-26SEP-H25","market_id":"749202d4-2a9a-4c24-b73a-116af982e245","price_dollars":"0.1500","delta_fp":"-141.00","side":"no","ts":"2026-09-11T15:43:41.976399Z","ts_ms":1789141421976}}
{"type":"orderbook_delta","sid":1,"seq":148,"msg":{"market_ticker":"KXFEDDECISION-26SEP-H25","market_id":"749202d4-2a9a-4c24-b73a-116af982e245","price_dollars":"0.8000","delta_fp":"200.00","side":"yes","ts":"2026-09-11T15:43:42.005305Z","ts_ms":1789141422005}}
{"type":"orderbook_delta","sid":1,"seq":149,"msg":{"market_ticker":"KXFEDDECISION-26SEP-H25","market_id":"749202d4-2a9a-4c24-b73a-116af982e245","price_dollars":"0.1400","delta_fp":"141.00","side":"no","ts":"2026-09-11T15:43:42.016969Z","ts_ms":1789141422016}}
{"type":"orderbook_delta","sid":1,"seq":150,"msg":{"market_ticker":"KXFEDDECISION-26SEP-H25","market_id":"749202d4-2a9a-4c24-b73a-116af982e245","price_dollars":"0.8000","delta_fp":"-200.00","side":"yes","ts":"2026-09-11T15:43:44.92024Z","ts_ms":1789141424920}}
{"type":"orderbook_delta","sid":1,"seq":151,"msg":{"market_ticker":"KXFEDDECISION-26SEP-H25","market_id":"749202d4-2a9a-4c24-b73a-116af982e245","price_dollars":"0.1400","delta_fp":"-141.00","side":"no","ts":"2026-09-11T15:43:44.922113Z","ts_ms":1789141424922}}
{"type":"orderbook_delta","sid":1,"seq":152,"msg":{"market_ticker":"KXFEDDECISION-26SEP-H25","market_id":"749202d4-2a9a-4c24-b73a-116af982e245","price_dollars":"0.7900","delta_fp":"200.00","side":"yes","ts":"2026-09-11T15:43:44.934515Z","ts_ms":1789141424934}}
{"type":"orderbook_delta","sid":1,"seq":153,"msg":{"market_ticker":"KXFEDDECISION-26SEP-H25","market_id":"749202d4-2a9a-4c24-b73a-116af982e245","price_dollars":"0.1500","delta_fp":"141.00","side":"no","ts":"2026-09-11T15:43:44.94373Z","ts_ms":1789141424943}}
{"type":"orderbook_delta","sid":1,"seq":154,"msg":{"market_ticker":"KXFEDDECISION-26SEP-H25","market_id":"749202d4-2a9a-4c24-b73a-116af982e245","price_dollars":"0.1400","delta_fp":"6448.00","side":"no","ts":"2026-09-11T15:43:48.583188Z","ts_ms":1789141428583}}
{"type":"orderbook_delta","sid":1,"seq":155,"msg":{"market_ticker":"KXFEDDECISION-26SEP-H25","market_id":"749202d4-2a9a-4c24-b73a-116af982e245","price_dollars":"0.1700","delta_fp":"-6858.00","side":"no","ts":"2026-09-11T15:43:51.32244Z","ts_ms":1789141431322}}
{"type":"orderbook_delta","sid":1,"seq":156,"msg":{"market_ticker":"KXFEDDECISION-26SEP-H25","market_id":"749202d4-2a9a-4c24-b73a-116af982e245","price_dollars":"0.1500","delta_fp":"-7973.00","side":"no","ts":"2026-09-11T15:43:52.894059Z","ts_ms":1789141432894}}
{"type":"orderbook_delta","sid":1,"seq":157,"msg":{"market_ticker":"KXFEDDECISION-26SEP-H25","market_id":"749202d4-2a9a-4c24-b73a-116af982e245","price_dollars":"0.1500","delta_fp":"-871.00","side":"no","ts":"2026-09-11T15:43:52.894073Z","ts_ms":1789141432894}}
{"type":"orderbook_delta","sid":1,"seq":158,"msg":{"market_ticker":"KXFEDDECISION-26SEP-H25","market_id":"749202d4-2a9a-4c24-b73a-116af982e245","price_dollars":"0.1500","delta_fp":"-445.00","side":"no","ts":"2026-09-11T15:43:52.894667Z","ts_ms":1789141432894}}
{"type":"orderbook_delta","sid":1,"seq":159,"msg":{"market_ticker":"KXFEDDECISION-26SEP-H25","market_id":"749202d4-2a9a-4c24-b73a-116af982e245","price_dollars":"0.1900","delta_fp":"-41.56","side":"no","ts":"2026-09-11T15:44:07.048403Z","ts_ms":1789141447048}}
{"type":"orderbook_delta","sid":1,"seq":160,"msg":{"market_ticker":"KXFEDDECISION-26SEP-H25","market_id":"749202d4-2a9a-4c24-b73a-116af982e245","price_dollars":"0.1900","delta_fp":"-10.00","side":"no","ts":"2026-09-11T15:44:07.048403Z","ts_ms":1789141447048}}
{"type":"orderbook_delta","sid":1,"seq":161,"msg":{"market_ticker":"KXFEDDECISION-26SEP-H25","market_id":"749202d4-2a9a-4c24-b73a-116af982e245","price_dollars":"0.1900","delta_fp":"-1183.00","side":"no","ts":"2026-09-11T15:44:07.048403Z","ts_ms":1789141447048}}
{"type":"orderbook_delta","sid":1,"seq":162,"msg":{"market_ticker":"KXFEDDECISION-26SEP-H25","market_id":"749202d4-2a9a-4c24-b73a-116af982e245","price_dollars":"0.7900","delta_fp":"10.00","side":"yes","ts":"2026-09-11T15:44:08.816484Z","ts_ms":1789141448816}}
{"type":"orderbook_delta","sid":1,"seq":163,"msg":{"market_ticker":"KXFEDDECISION-26SEP-H25","market_id":"749202d4-2a9a-4c24-b73a-116af982e245","price_dollars":"0.7700","delta_fp":"15.00","side":"yes","ts":"2026-09-11T15:44:08.817781Z","ts_ms":1789141448817}}
{"type":"orderbook_delta","sid":1,"seq":164,"msg":{"market_ticker":"KXFEDDECISION-26SEP-H25","market_id":"749202d4-2a9a-4c24-b73a-116af982e245","price_dollars":"0.1500","delta_fp":"10.00","side":"no","ts":"2026-09-11T15:44:15.59208Z","ts_ms":1789141455592}}
{"type":"orderbook_delta","sid":1,"seq":165,"msg":{"market_ticker":"KXFEDDECISION-26SEP-H25","market_id":"749202d4-2a9a-4c24-b73a-116af982e245","price_dollars":"0.8000","delta_fp":"-1112.68","side":"yes","ts":"2026-09-11T15:44:26.400378Z","ts_ms":1789141466400}}
{"type":"orderbook_delta","sid":1,"seq":166,"msg":{"market_ticker":"KXFEDDECISION-26SEP-H25","market_id":"749202d4-2a9a-4c24-b73a-116af982e245","price_dollars":"0.7800","delta_fp":"-1035.00","side":"yes","ts":"2026-09-11T15:44:26.534607Z","ts_ms":1789141466534}}
{"type":"orderbook_delta","sid":1,"seq":167,"msg":{"market_ticker":"KXFEDDECISION-26SEP-H25","market_id":"749202d4-2a9a-4c24-b73a-116af982e245","price_dollars":"0.1700","delta_fp":"-1.00","side":"no","ts":"2026-09-11T15:44:27.089289Z","ts_ms":1789141467089}}
{"type":"orderbook_delta","sid":1,"seq":168,"msg":{"market_ticker":"KXFEDDECISION-26SEP-H25","market_id":"749202d4-2a9a-4c24-b73a-116af982e245","price_dollars":"0.1700","delta_fp":"-4.00","side":"no","ts":"2026-09-11T15:44:27.176617Z","ts_ms":1789141467176}}
{"type":"orderbook_delta","sid":1,"seq":169,"msg":{"market_ticker":"KXFEDDECISION-26SEP-H25","market_id":"749202d4-2a9a-4c24-b73a-116af982e245","price_dollars":"0.1500","delta_fp":"9294.00","side":"no","ts":"2026-09-11T15:44:36.066971Z","ts_ms":1789141476066}}
{"type":"orderbook_delta","sid":1,"seq":170,"msg":{"market_ticker":"KXFEDDECISION-26SEP-H25","market_id":"749202d4-2a9a-4c24-b73a-116af982e245","price_dollars":"0.1400","delta_fp":"-4.00","side":"no","ts":"2026-09-11T15:44:38.694192Z","ts_ms":1789141478694}}
{"type":"orderbook_delta","sid":1,"seq":171,"msg":{"market_ticker":"KXFEDDECISION-26SEP-H25","market_id":"749202d4-2a9a-4c24-b73a-116af982e245","price_dollars":"0.1900","delta_fp":"-349.55","side":"no","ts":"2026-09-11T15:45:03.062549Z","ts_ms":1789141503062}}
{"type":"orderbook_delta","sid":1,"seq":172,"msg":{"market_ticker":"KXFEDDECISION-26SEP-H25","market_id":"749202d4-2a9a-4c24-b73a-116af982e245","price_dollars":"0.1900","delta_fp":"-42.64","side":"no","ts":"2026-09-11T15:45:09.897978Z","ts_ms":1789141509897}}
{"type":"orderbook_delta","sid":1,"seq":173,"msg":{"market_ticker":"KXFEDDECISION-26SEP-H25","market_id":"749202d4-2a9a-4c24-b73a-116af982e245","price_dollars":"0.8000","delta_fp":"100.00","side":"yes","ts":"2026-09-11T15:45:12.718677Z","ts_ms":1789141512718}}
{"type":"orderbook_delta","sid":1,"seq":174,"msg":{"market_ticker":"KXFEDDECISION-26SEP-H25","market_id":"749202d4-2a9a-4c24-b73a-116af982e245","price_dollars":"0.1500","delta_fp":"1860.00","side":"no","ts":"2026-09-11T15:45:43.925286Z","ts_ms":1789141543925}}
{"type":"orderbook_delta","sid":1,"seq":175,"msg":{"market_ticker":"KXFEDDECISION-26SEP-H25","market_id":"749202d4-2a9a-4c24-b73a-116af982e245","price_dollars":"0.1500","delta_fp":"3418.00","side":"no","ts":"2026-09-11T15:46:03.530501Z","ts_ms":1789141563530}}
{"type":"orderbook_delta","sid":1,"seq":176,"msg":{"market_ticker":"KXFEDDECISION-26SEP-H25","market_id":"749202d4-2a9a-4c24-b73a-116af982e245","price_dollars":"0.1700","delta_fp":"33600.00","side":"no","ts":"2026-09-11T15:46:28.584598Z","ts_ms":1789141588584}}
{"type":"orderbook_delta","sid":1,"seq":177,"msg":{"market_ticker":"KXFEDDECISION-26SEP-H25","market_id":"749202d4-2a9a-4c24-b73a-116af982e245","price_dollars":"0.1700","delta_fp":"-100.00","side":"no","ts":"2026-09-11T15:46:29.02506Z","ts_ms":1789141589025}}
{"type":"orderbook_delta","sid":1,"seq":178,"msg":{"market_ticker":"KXFEDDECISION-26SEP-H25","market_id":"749202d4-2a9a-4c24-b73a-116af982e245","price_dollars":"0.1600","delta_fp":"-100.00","side":"no","ts":"2026-09-11T15:46:29.025663Z","ts_ms":1789141589025}}
{"type":"orderbook_delta","sid":1,"seq":179,"msg":{"market_ticker":"KXFEDDECISION-26SEP-H25","market_id":"749202d4-2a9a-4c24-b73a-116af982e245","price_dollars":"0.1800","delta_fp":"-5000.00","side":"no","ts":"2026-09-11T15:46:34.943083Z","ts_ms":1789141594943}}
{"type":"orderbook_delta","sid":1,"seq":180,"msg":{"market_ticker":"KXFEDDECISION-26SEP-H25","market_id":"749202d4-2a9a-4c24-b73a-116af982e245","price_dollars":"0.1900","delta_fp":"5000.00","side":"no","ts":"2026-09-11T15:46:34.943083Z","ts_ms":1789141594943}}
{"type":"orderbook_delta","sid":1,"seq":181,"msg":{"market_ticker":"KXFEDDECISION-26SEP-H25","market_id":"749202d4-2a9a-4c24-b73a-116af982e245","price_dollars":"0.8000","delta_fp":"-50.00","side":"yes","ts":"2026-09-11T15:46:50.041926Z","ts_ms":1789141610041}}
{"type":"orderbook_delta","sid":1,"seq":182,"msg":{"market_ticker":"KXFEDDECISION-26SEP-H25","market_id":"749202d4-2a9a-4c24-b73a-116af982e245","price_dollars":"0.1800","delta_fp":"2.00","side":"no","ts":"2026-09-11T15:46:51.041341Z","ts_ms":1789141611041}}
{"type":"orderbook_delta","sid":1,"seq":183,"msg":{"market_ticker":"KXFEDDECISION-26SEP-H25","market_id":"749202d4-2a9a-4c24-b73a-116af982e245","price_dollars":"0.1900","delta_fp":"-5000.00","side":"no","ts":"2026-09-11T15:46:55.064546Z","ts_ms":1789141615064}}
{"type":"orderbook_delta","sid":1,"seq":184,"msg":{"market_ticker":"KXFEDDECISION-26SEP-H25","market_id":"749202d4-2a9a-4c24-b73a-116af982e245","price_dollars":"0.1800","delta_fp":"5000.00","side":"no","ts":"2026-09-11T15:46:55.064546Z","ts_ms":1789141615064}}
{"type":"orderbook_delta","sid":1,"seq":185,"msg":{"market_ticker":"KXFEDDECISION-26SEP-H25","market_id":"749202d4-2a9a-4c24-b73a-116af982e245","price_dollars":"0.1800","delta_fp":"-2.00","side":"no","ts":"2026-09-11T15:47:00.181933Z","ts_ms":1789141620181}}
{"type":"orderbook_delta","sid":1,"seq":186,"msg":{"market_ticker":"KXFEDDECISION-26SEP-H25","market_id":"749202d4-2a9a-4c24-b73a-116af982e245","price_dollars":"0.1900","delta_fp":"-1.82","side":"no","ts":"2026-09-11T15:47:05.834202Z","ts_ms":1789141625834}}
{"type":"orderbook_delta","sid":1,"seq":187,"msg":{"market_ticker":"KXFEDDECISION-26SEP-H25","market_id":"749202d4-2a9a-4c24-b73a-116af982e245","price_dollars":"0.1700","delta_fp":"-1600.00","side":"no","ts":"2026-09-11T15:47:06.913314Z","ts_ms":1789141626913}}
{"type":"orderbook_delta","sid":1,"seq":188,"msg":{"market_ticker":"KXFEDDECISION-26SEP-H25","market_id":"749202d4-2a9a-4c24-b73a-116af982e245","price_dollars":"0.7800","delta_fp":"-1214.00","side":"yes","ts":"2026-09-11T15:47:13.737672Z","ts_ms":1789141633737}}
{"type":"orderbook_delta","sid":1,"seq":189,"msg":{"market_ticker":"KXFEDDECISION-26SEP-H25","market_id":"749202d4-2a9a-4c24-b73a-116af982e245","price_dollars":"0.8000","delta_fp":"-2.36","side":"yes","ts":"2026-09-11T15:47:15.743503Z","ts_ms":1789141635743}}
{"type":"orderbook_delta","sid":1,"seq":190,"msg":{"market_ticker":"KXFEDDECISION-26SEP-H25","market_id":"749202d4-2a9a-4c24-b73a-116af982e245","price_dollars":"0.1800","delta_fp":"2.00","side":"no","ts":"2026-09-11T15:47:19.067597Z","ts_ms":1789141639067}}
{"type":"orderbook_delta","sid":1,"seq":191,"msg":{"market_ticker":"KXFEDDECISION-26SEP-H25","market_id":"749202d4-2a9a-4c24-b73a-116af982e245","price_dollars":"0.1800","delta_fp":"-2.00","side":"no","ts":"2026-09-11T15:47:25.103967Z","ts_ms":1789141645103}}
{"type":"orderbook_delta","sid":1,"seq":192,"msg":{"market_ticker":"KXFEDDECISION-26SEP-H25","market_id":"749202d4-2a9a-4c24-b73a-116af982e245","price_dollars":"0.1800","delta_fp":"2000.00","side":"no","ts":"2026-09-11T15:47:29.705645Z","ts_ms":1789141649705}}
{"type":"orderbook_delta","sid":1,"seq":193,"msg":{"market_ticker":"KXFEDDECISION-26SEP-H25","market_id":"749202d4-2a9a-4c24-b73a-116af982e245","price_dollars":"0.1800","delta_fp":"1000.00","side":"no","ts":"2026-09-11T15:47:38.481095Z","ts_ms":1789141658481}}
{"type":"orderbook_delta","sid":1,"seq":194,"msg":{"market_ticker":"KXFEDDECISION-26SEP-H25","market_id":"749202d4-2a9a-4c24-b73a-116af982e245","price_dollars":"0.1900","delta_fp":"-109.67","side":"no","ts":"2026-09-11T15:47:55.218154Z","ts_ms":1789141675218}}
{"type":"orderbook_delta","sid":1,"seq":195,"msg":{"market_ticker":"KXFEDDECISION-26SEP-H25","market_id":"749202d4-2a9a-4c24-b73a-116af982e245","price_dollars":"0.8000","delta_fp":"-634.46","side":"yes","ts":"2026-09-11T15:47:55.898746Z","ts_ms":1789141675898}}
{"type":"orderbook_delta","sid":1,"seq":196,"msg":{"market_ticker":"KXFEDDECISION-26SEP-H25","market_id":"749202d4-2a9a-4c24-b73a-116af982e245","price_dollars":"0.7800","delta_fp":"-29.00","side":"yes","ts":"2026-09-11T15:47:56.029318Z","ts_ms":1789141676029}}
{"type":"orderbook_delta","sid":1,"seq":197,"msg":{"market_ticker":"KXFEDDECISION-26SEP-H25","market_id":"749202d4-2a9a-4c24-b73a-116af982e245","price_dollars":"0.7800","delta_fp":"-563.00","side":"yes","ts":"2026-09-11T15:47:56.029344Z","ts_ms":1789141676029}}
{"type":"orderbook_delta","sid":1,"seq":198,"msg":{"market_ticker":"KXFEDDECISION-26SEP-H25","market_id":"749202d4-2a9a-4c24-b73a-116af982e245","price_dollars":"0.8000","delta_fp":"-2367.40","side":"yes","ts":"2026-09-11T15:48:20.846469Z","ts_ms":1789141700846}}
{"type":"orderbook_delta","sid":1,"seq":199,"msg":{"market_ticker":"KXFEDDECISION-26SEP-H25","market_id":"749202d4-2a9a-4c24-b73a-116af982e245","price_dollars":"0.7800","delta_fp":"-2219.00","side":"yes","ts":"2026-09-11T15:48:20.977841Z","ts_ms":1789141700977}}
{"type":"orderbook_delta","sid":1,"seq":200,"msg":{"market_ticker":"KXFEDDECISION-26SEP-H25","market_id":"749202d4-2a9a-4c24-b73a-116af982e245","price_dollars":"0.4000","delta_fp":"2367.40","side":"yes","ts":"2026-09-11T15:48:41.012299Z","ts_ms":1789141721012}}
{"type":"orderbook_delta","sid":1,"seq":201,"msg":{"market_ticker":"KXFEDDECISION-26SEP-H25","market_id":"749202d4-2a9a-4c24-b73a-116af982e245","price_dollars":"0.8000","delta_fp":"-50.00","side":"yes","ts":"2026-09-11T15:48:50.14059Z","ts_ms":1789141730140}}
{"type":"orderbook_delta","sid":1,"seq":202,"msg":{"market_ticker":"KXFEDDECISION-26SEP-H25","market_id":"749202d4-2a9a-4c24-b73a-116af982e245","price_dollars":"0.7800","delta_fp":"4833.00","side":"yes","ts":"2026-09-11T15:48:56.860295Z","ts_ms":1789141736860}}
