{"market":"0x876506d8b2bd7a0d3fa4fe18c024eee6e1dd81ee24c26795dadd6cfe4a7b5d0d", "price_changes":[{"asset_id":"63842529068710005716169325380315470359047749786610778647370693404952498013178", "price":"0.81", "size":"13121.73", "side":"BUY", "hash":"ed44e79269114a1ff424bc1a989ee3143aaa0fb5", "best_bid":"0.81", "best_ask":"0.82"}, {"asset_id":"2881957189963819690709899387312951271986076905757701114514025622922000576600", "price":"0.19", "size":"13121.73", "side":"SELL", "hash":"c28fe7cbe0c22b6f8abb2c0d01ec6ccfded601f1", "best_bid":"0.18", "best_ask":"0.19"}], "timestamp":"1789143364638", "event_type":"price_change"}
{"market":"0x876506d8b2bd7a0d3fa4fe18c024eee6e1dd81ee24c26795dadd6cfe4a7b5d0d", "price_changes":[{"asset_id":"63842529068710005716169325380315470359047749786610778647370693404952498013178", "price":"0.01", "size":"1103682.45", "side":"BUY", "hash":"d0caee774bada6d90ccd03bb8049e575f0c08156", "best_bid":"0.81", "best_ask":"0.82"}, {"asset_id":"2881957189963819690709899387312951271986076905757701114514025622922000576600", "price":"0.99", "size":"1103682.45", "side":"SELL", "hash":"da14c4baf75302c21c754a3c2f458e46a0101a86", "best_bid":"0.18", "best_ask":"0.19"}], "timestamp":"1789143368202", "event_type":"price_change"}
{"market":"0x876506d8b2bd7a0d3fa4fe18c024eee6e1dd81ee24c26795dadd6cfe4a7b5d0d", "price_changes":[{"asset_id":"2881957189963819690709899387312951271986076905757701114514025622922000576600", "price":"0.01", "size":"2253302.07", "side":"BUY", "hash":"48f5f38492033e6da027eb364986ab903d60fc19", "best_bid":"0.18", "best_ask":"0.19"}, {"asset_id":"63842529068710005716169325380315470359047749786610778647370693404952498013178", "price":"0.99", "size":"2253302.07", "side":"SELL", "hash":"e3c1c45978a3f8f434bcb63f8b18d1e769952bf0", "best_bid":"0.81", "best_ask":"0.82"}], "timestamp":"1789143368283", "event_type":"price_change"}
{"market":"0x876506d8b2bd7a0d3fa4fe18c024eee6e1dd81ee24c26795dadd6cfe4a7b5d0d", "price_changes":[{"asset_id":"63842529068710005716169325380315470359047749786610778647370693404952498013178", "price":"0.01", "size":"1103692.45", "side":"BUY", "hash":"794c040ca9072891b6a32c8333ec58317d30e808", "best_bid":"0.81", "best_ask":"0.82"}, {"asset_id":"2881957189963819690709899387312951271986076905757701114514025622922000576600", "price":"0.99", "size":"1103692.45", "side":"SELL", "hash":"ac0f54b3a6847c08c481fd22e66f56ccb3db4968", "best_bid":"0.18", "best_ask":"0.19"}], "timestamp":"1789143368782", "event_type":"price_change"}
{"market":"0x876506d8b2bd7a0d3fa4fe18c024eee6e1dd81ee24c26795dadd6cfe4a7b5d0d", "price_changes":[{"asset_id":"2881957189963819690709899387312951271986076905757701114514025622922000576600", "price":"0.01", "size":"2253312.07", "side":"BUY", "hash":"d24ad1bc5ae7024c3f95c265adc54457ea25addf", "best_bid":"0.18", "best_ask":"0.19"}, {"asset_id":"63842529068710005716169325380315470359047749786610778647370693404952498013178", "price":"0.99", "size":"2253312.07", "side":"SELL", "hash":"801f80d47a18ff8600503b08fb610ad2feaf12cd", "best_bid":"0.81", "best_ask":"0.82"}], "timestamp":"1789143368870", "event_type":"price_change"}
{"market":"0x876506d8b2bd7a0d3fa4fe18c024eee6e1dd81ee24c26795dadd6cfe4a7b5d0d", "price_changes":[{"asset_id":"63842529068710005716169325380315470359047749786610778647370693404952498013178", "price":"0.74", "size":"2000", "side":"BUY", "hash":"2bda20ca6dfdf651457c5c10090a000d05004dcf", "best_bid":"0.81", "best_ask":"0.82"}, {"asset_id":"2881957189963819690709899387312951271986076905757701114514025622922000576600", "price":"0.26", "size":"2000", "side":"SELL", "hash":"be15a70a3aa2174cf3b2c2d5f95f4f915de5f708", "best_bid":"0.18", "best_ask":"0.19"}], "timestamp":"1789143373001", "event_type":"price_change"}
{"market":"0x876506d8b2bd7a0d3fa4fe18c024eee6e1dd81ee24c26795dadd6cfe4a7b5d0d", "price_changes":[{"asset_id":"63842529068710005716169325380315470359047749786610778647370693404952498013178", "price":"0.74", "size":"2200", "side":"BUY", "hash":"5f5e7b17af371165f4192f13976379adb1a3c2d1", "best_bid":"0.81", "best_ask":"0.82"}, {"asset_id":"2881957189963819690709899387312951271986076905757701114514025622922000576600", "price":"0.26", "size":"2200", "side":"SELL", "hash":"25cab9b75371f7f347d73de8db015a67fd83d21c", "best_bid":"0.18", "best_ask":"0.19"}], "timestamp":"1789143373226", "event_type":"price_change"}
{"market":"0x876506d8b2bd7a0d3fa4fe18c024eee6e1dd81ee24c26795dadd6cfe4a7b5d0d", "price_changes":[{"asset_id":"2881957189963819690709899387312951271986076905757701114514025622922000576600", "price":"0.13", "size":"37050", "side":"BUY", "hash":"46f14c3017a416788625ba14eec9db9df1c0c19d", "best_bid":"0.18", "best_ask":"0.19"}, {"asset_id":"63842529068710005716169325380315470359047749786610778647370693404952498013178", "price":"0.87", "size":"37050", "side":"SELL", "hash":"7b3b1595274fdce443714535613efa93f99b8b7d", "best_bid":"0.81", "best_ask":"0.82"}], "timestamp":"1789143375591", "event_type":"price_change"}
{"market":"0x876506d8b2bd7a0d3fa4fe18c024eee6e1dd81ee24c26795dadd6cfe4a7b5d0d", "price_changes":[{"asset_id":"2881957189963819690709899387312951271986076905757701114514025622922000576600", "price":"0.17", "size":"69168.19", "side":"BUY", "hash":"5a77c32628ddc77e88a163411103041d18c120f3", "best_bid":"0.18", "best_ask":"0.19"}, {"asset_id":"63842529068710005716169325380315470359047749786610778647370693404952498013178", "price":"0.83", "size":"69168.19", "side":"SELL", "hash":"16ccc54d588cfce6e1b2968dca7825a3ac130bb7", "best_bid":"0.81", "best_ask":"0.82"}], "timestamp":"1789143375632", "event_type":"price_change"}
{"market":"0x876506d8b2bd7a0d3fa4fe18c024eee6e1dd81ee24c26795dadd6cfe4a7b5d0d", "price_changes":[{"asset_id":"2881957189963819690709899387312951271986076905757701114514025622922000576600", "price":"0.02", "size":"57280.6", "side":"BUY", "hash":"fd75bb697e5a42a0792da8acc9358f8e44693217", "best_bid":"0.18", "best_ask":"0.19"}, {"asset_id":"63842529068710005716169325380315470359047749786610778647370693404952498013178", "price":"0.98", "size":"57280.6", "side":"SELL", "hash":"e5f1abea687f7f5c5f91a6c4b7a56e94386fb005", "best_bid":"0.81", "best_ask":"0.82"}], "timestamp":"1789143375656", "event_type":"price_change"}
{"market":"0x876506d8b2bd7a0d3fa4fe18c024eee6e1dd81ee24c26795dadd6cfe4a7b5d0d", "price_changes":[{"asset_id":"2881957189963819690709899387312951271986076905757701114514025622922000576600", "price":"0.13", "size":"37250", "side":"BUY", "hash":"a2c5c4c53697a4f6f7e7e291cd5d915ba4fa8483", "best_bid":"0.18", "best_ask":"0.19"}, {"asset_id":"63842529068710005716169325380315470359047749786610778647370693404952498013178", "price":"0.87", "size":"37250", "side":"SELL", "hash":"ec1e7f00a293995fc65c837d205cc3dc449a7830", "best_bid":"0.81", "best_ask":"0.82"}], "timestamp":"1789143375905", "event_type":"price_change"}
{"market":"0x876506d8b2bd7a0d3fa4fe18c024eee6e1dd81ee24c26795dadd6cfe4a7b5d0d", "price_changes":[{"asset_id":"2881957189963819690709899387312951271986076905757701114514025622922000576600", "price":"0.17", "size":"70168.19", "side":"BUY", "hash":"32349605feb89f49e741714d5f28313ddd0230d9", "best_bid":"0.18", "best_ask":"0.19"}, {"asset_id":"63842529068710005716169325380315470359047749786610778647370693404952498013178", "price":"0.83", "size":"70168.19", "side":"SELL", "hash":"0da502abd7dd83c45ce95778b728df4fa60b94ea", "best_bid":"0.81", "best_ask":"0.82"}], "timestamp":"1789143384039", "event_type":"price_change"}
{"market":"0x876506d8b2bd7a0d3fa4fe18c024eee6e1dd81ee24c26795dadd6cfe4a7b5d0d", "price_changes":[{"asset_id":"2881957189963819690709899387312951271986076905757701114514025622922000576600", "price":"0.17", "size":"69168.19", "side":"BUY", "hash":"79e409391054ad39b5b838a70b2ecd87f656f2ae", "best_bid":"0.18", "best_ask":"0.19"}, {"asset_id":"63842529068710005716169325380315470359047749786610778647370693404952498013178", "price":"0.83", "size":"69168.19", "side":"SELL", "hash":"7c257ee7df75e78c4930613274934754e75bb2a6", "best_bid":"0.81", "best_ask":"0.82"}], "timestamp":"1789143384091", "event_type":"price_change"}
{"market":"0x876506d8b2bd7a0d3fa4fe18c024eee6e1dd81ee24c26795dadd6cfe4a7b5d0d", "price_changes":[{"asset_id":"63842529068710005716169325380315470359047749786610778647370693404952498013178", "price":"0.71", "size":"6769.73", "side":"BUY", "hash":"29aadbb532163ed29a47580d9588b8c158b4907d", "best_bid":"0.81", "best_ask":"0.82"}, {"asset_id":"2881957189963819690709899387312951271986076905757701114514025622922000576600", "price":"0.29", "size":"6769.73", "side":"SELL", "hash":"f50c1241c63b58d36698970b964fc84c6029bac0", "best_bid":"0.18", "best_ask":"0.19"}], "timestamp":"1789143384111", "event_type":"price_change"}
{"market":"0x876506d8b2bd7a0d3fa4fe18c024eee6e1dd81ee24c26795dadd6cfe4a7b5d0d", "price_changes":[{"asset_id":"2881957189963819690709899387312951271986076905757701114514025622922000576600", "price":"0.01", "size":"2253512.07", "side":"BUY", "hash":"0f32399149db457f18ddf87ebe865d560e28ea13", "best_bid":"0.18", "best_ask":"0.19"}, {"asset_id":"63842529068710005716169325380315470359047749786610778647370693404952498013178", "price":"0.99", "size":"2253512.07", "side":"SELL", "hash":"a305667954b8438737c4021a574071aa38eb904c", "best_bid":"0.81", "best_ask":"0.82"}], "timestamp":"1789143384112", "event_type":"price_change"}
{"market":"0x876506d8b2bd7a0d3fa4fe18c024eee6e1dd81ee24c26795dadd6cfe4a7b5d0d", "price_changes":[{"asset_id":"63842529068710005716169325380315470359047749786610778647370693404952498013178", "price":"0.01", "size":"1103682.45", "side":"BUY", "hash":"15dcf71cc31a4c93da79055ec7855b72fcb86087", "best_bid":"0.81", "best_ask":"0.82"}, {"asset_id":"2881957189963819690709899387312951271986076905757701114514025622922000576600", "price":"0.99", "size":"1103682.45", "side":"SELL", "hash":"296cc1ef475dfa56f97ec1d10f9c261008a085a5", "best_bid":"0.18", "best_ask":"0.19"}], "timestamp":"1789143387534", "event_type":"price_change"}
{"market":"0x876506d8b2bd7a0d3fa4fe18c024eee6e1dd81ee24c26795dadd6cfe4a7b5d0d", "price_changes":[{"asset_id":"2881957189963819690709899387312951271986076905757701114514025622922000576600", "price":"0.01", "size":"2253502.07", "side":"BUY", "hash":"927349ca6de991bb6c7511324523b629f61e8bb2", "best_bid":"0.18", "best_ask":"0.19"}, {"asset_id":"63842529068710005716169325380315470359047749786610778647370693404952498013178", "price":"0.99", "size":"2253502.07", "side":"SELL", "hash":"890fe457baae378d758ab74a21f5d7ef0274518c", "best_bid":"0.81", "best_ask":"0.82"}], "timestamp":"1789143387623", "event_type":"price_change"}
{"market":"0x876506d8b2bd7a0d3fa4fe18c024eee6e1dd81ee24c26795dadd6cfe4a7b5d0d", "price_changes":[{"asset_id":"2881957189963819690709899387312951271986076905757701114514025622922000576600", "price":"0.01", "size":"2253552.07", "side":"BUY", "hash":"1a7a9bfe205b3f23b9ea1b633fbfaa5b2d561e82", "best_bid":"0.18", "best_ask":"0.19"}, {"asset_id":"63842529068710005716169325380315470359047749786610778647370693404952498013178", "price":"0.99", "size":"2253552.07", "side":"SELL", "hash":"58e7633521fa00664ec067450f3310c01d5a488e", "best_bid":"0.81", "best_ask":"0.82"}], "timestamp":"1789143387735", "event_type":"price_change"}
{"market":"0x876506d8b2bd7a0d3fa4fe18c024eee6e1dd81ee24c26795dadd6cfe4a7b5d0d", "price_changes":[{"asset_id":"63842529068710005716169325380315470359047749786610778647370693404952498013178", "price":"0.81", "size":"13171.73", "side":"BUY", "hash":"305f25635cfd585088a9988b6910c96dd37e3437", "best_bid":"0.81", "best_ask":"0.82"}, {"asset_id":"2881957189963819690709899387312951271986076905757701114514025622922000576600", "price":"0.19", "size":"13171.73", "side":"SELL", "hash":"d11751044ff42aa63415c04b76a4fbf72bdf2198", "best_bid":"0.18", "best_ask":"0.19"}], "timestamp":"1789143387735", "event_type":"price_change"}
{"market":"0x876506d8b2bd7a0d3fa4fe18c024eee6e1dd81ee24c26795dadd6cfe4a7b5d0d", "price_changes":[{"asset_id":"63842529068710005716169325380315470359047749786610778647370693404952498013178", "price":"0.01", "size":"1103692.45", "side":"BUY", "hash":"20b86c5579aeb400d45238b25f15c4681a35afad", "best_bid":"0.81", "best_ask":"0.82"}, {"asset_id":"2881957189963819690709899387312951271986076905757701114514025622922000576600", "price":"0.99", "size":"1103692.45", "side":"SELL", "hash":"a095deac387f298cf682d269884e05d803f0551a", "best_bid":"0.18", "best_ask":"0.19"}], "timestamp":"1789143388027", "event_type":"price_change"}
{"market":"0x876506d8b2bd7a0d3fa4fe18c024eee6e1dd81ee24c26795dadd6cfe4a7b5d0d", "price_changes":[{"asset_id":"2881957189963819690709899387312951271986076905757701114514025622922000576600", "price":"0.01", "size":"2253562.07", "side":"BUY", "hash":"3e1e1481d6fd21f5c115521252216f3daea82fad", "best_bid":"0.18", "best_ask":"0.19"}, {"asset_id":"63842529068710005716169325380315470359047749786610778647370693404952498013178", "price":"0.99", "size":"2253562.07", "side":"SELL", "hash":"73cd54136fbb2a366e41ad85bde94f422f6eb952", "best_bid":"0.81", "best_ask":"0.82"}], "timestamp":"1789143388115", "event_type":"price_change"}
{"market":"0x876506d8b2bd7a0d3fa4fe18c024eee6e1dd81ee24c26795dadd6cfe4a7b5d0d", "price_changes":[{"asset_id":"2881957189963819690709899387312951271986076905757701114514025622922000576600", "price":"0.05", "size":"31622", "side":"BUY", "hash":"7d80456e387de0f061eb8349e2305e3a5db75781", "best_bid":"0.18", "best_ask":"0.19"}, {"asset_id":"63842529068710005716169325380315470359047749786610778647370693404952498013178", "price":"0.95", "size":"31622", "side":"SELL", "hash":"372017a41546e93b8c7cd9815d90cb3566572231", "best_bid":"0.81", "best_ask":"0.82"}], "timestamp":"1789143389087", "event_type":"price_change"}
{"market":"0x876506d8b2bd7a0d3fa4fe18c024eee6e1dd81ee24c26795dadd6cfe4a7b5d0d", "price_changes":[{"asset_id":"2881957189963819690709899387312951271986076905757701114514025622922000576600", "price":"0.5", "size":"30", "side":"SELL", "hash":"da4b8d6a9c5ad81548eb8f85a6f1053533c1d502", "best_bid":"0.18", "best_ask":"0.19"}, {"asset_id":"63842529068710005716169325380315470359047749786610778647370693404952498013178", "price":"0.5", "size":"30", "side":"BUY", "hash":"33617db0f897bf820842b5b9ab382baeb31aaeb8", "best_bid":"0.81", "best_ask":"0.82"}], "timestamp":"1789143389752", "event_type":"price_change"}
{"market":"0x876506d8b2bd7a0d3fa4fe18c024eee6e1dd81ee24c26795dadd6cfe4a7b5d0d", "price_changes":[{"asset_id":"2881957189963819690709899387312951271986076905757701114514025622922000576600", "price":"0.17", "size":"65668.19", "side":"BUY", "hash":"5d687c7b329d1060b718262e0bb7af6d7b8be226", "best_bid":"0.18", "best_ask":"0.19"}, {"asset_id":"63842529068710005716169325380315470359047749786610778647370693404952498013178", "price":"0.83", "size":"65668.19", "side":"SELL", "hash":"a15af3a64b49480b49e5e98da78ee82e54ce0c6f", "best_bid":"0.81", "best_ask":"0.82"}], "timestamp":"1789143390000", "event_type":"price_change"}
{"market":"0x876506d8b2bd7a0d3fa4fe18c024eee6e1dd81ee24c26795dadd6cfe4a7b5d0d", "price_changes":[{"asset_id":"2881957189963819690709899387312951271986076905757701114514025622922000576600", "price":"0.05", "size":"31722", "side":"BUY", "hash":"a3ca9da3cce7304b9d1e88a648ceceb57d6f9d5f", "best_bid":"0.18", "best_ask":"0.19"}, {"asset_id":"63842529068710005716169325380315470359047749786610778647370693404952498013178", "price":"0.95", "size":"31722", "side":"SELL", "hash":"d3137344aea0bbfb8a01c291597a0f77794ebf8f", "best_bid":"0.81", "best_ask":"0.82"}], "timestamp":"1789143397445", "event_type":"price_change"}
{"market":"0x876506d8b2bd7a0d3fa4fe18c024eee6e1dd81ee24c26795dadd6cfe4a7b5d0d", "price_changes":[{"asset_id":"2881957189963819690709899387312951271986076905757701114514025622922000576600", "price":"0.15", "size":"76819", "side":"BUY", "hash":"a0b81e9f52f0593a69eb6920c5b9ba8c156b958d", "best_bid":"0.18", "best_ask":"0.19"}, {"asset_id":"63842529068710005716169325380315470359047749786610778647370693404952498013178", "price":"0.85", "size":"76819", "side":"SELL", "hash":"1dde48f73d6d3fa23fb6e3f19d23f3c1fbdd61c0", "best_bid":"0.81", "best_ask":"0.82"}], "timestamp":"1789143401271", "event_type":"price_change"}
{"market":"0x876506d8b2bd7a0d3fa4fe18c024eee6e1dd81ee24c26795dadd6cfe4a7b5d0d", "price_changes":[{"asset_id":"2881957189963819690709899387312951271986076905757701114514025622922000576600", "price":"0.15", "size":"76894", "side":"BUY", "hash":"56b2fcfb7807fef19189a3eaca15fa756cf30263", "best_bid":"0.18", "best_ask":"0.19"}, {"asset_id":"63842529068710005716169325380315470359047749786610778647370693404952498013178", "price":"0.85", "size":"76894", "side":"SELL", "hash":"922b9aa0c0c0688383339f55371b28b2618fd9bc", "best_bid":"0.81", "best_ask":"0.82"}], "timestamp":"1789143403526", "event_type":"price_change"}
{"market":"0x876506d8b2bd7a0d3fa4fe18c024eee6e1dd81ee24c26795dadd6cfe4a7b5d0d", "price_changes":[{"asset_id":"2881957189963819690709899387312951271986076905757701114514025622922000576600", "price":"0.17", "size":"69168.19", "side":"BUY", "hash":"f707cb4bd17b806d3e297c20fb9b09bb67aca827", "best_bid":"0.18", "best_ask":"0.19"}, {"asset_id":"63842529068710005716169325380315470359047749786610778647370693404952498013178", "price":"0.83", "size":"69168.19", "side":"SELL", "hash":"2f17af90fc92fa3c108dfd38a9ed94dbdf168220", "best_bid":"0.81", "best_ask":"0.82"}], "timestamp":"1789143403648", "event_type":"price_change"}
{"market":"0x876506d8b2bd7a0d3fa4fe18c024eee6e1dd81ee24c26795dadd6cfe4a7b5d0d", "price_changes":[{"asset_id":"2881957189963819690709899387312951271986076905757701114514025622922000576600", "price":"0.17", "size":"70168.19", "side":"BUY", "hash":"2932ce67dc901e18c6da27fbb4ec1e291448809c", "best_bid":"0.18", "best_ask":"0.19"}, {"asset_id":"63842529068710005716169325380315470359047749786610778647370693404952498013178", "price":"0.83", "size":"70168.19", "side":"SELL", "hash":"b37820d76969469cdc12e9b4ab936143a83e8310", "best_bid":"0.81", "best_ask":"0.82"}], "timestamp":"1789143404211", "event_type":"price_change"}
{"market":"0x876506d8b2bd7a0d3fa4fe18c024eee6e1dd81ee24c26795dadd6cfe4a7b5d0d", "price_changes":[{"asset_id":"2881957189963819690709899387312951271986076905757701114514025622922000576600", "price":"0.17", "size":"69168.19", "side":"BUY", "hash":"10d5e52e61827650daf70542772274da34fd2d53", "best_bid":"0.18", "best_ask":"0.19"}, {"asset_id":"63842529068710005716169325380315470359047749786610778647370693404952498013178", "price":"0.83", "size":"69168.19", "side":"SELL", "hash":"142d8d2467fb201147e43f1f494d0974e58e7a5b", "best_bid":"0.81", "best_ask":"0.82"}], "timestamp":"1789143404280", "event_type":"price_change"}
{"market":"0x876506d8b2bd7a0d3fa4fe18c024eee6e1dd81ee24c26795dadd6cfe4a7b5d0d", "price_changes":[{"asset_id":"63842529068710005716169325380315470359047749786610778647370693404952498013178", "price":"0.78", "size":"24335.62", "side":"BUY", "hash":"2368cbe79e591e2f467cc2c64bcfe88499681837", "best_bid":"0.81", "best_ask":"0.82"}, {"asset_id":"2881957189963819690709899387312951271986076905757701114514025622922000576600", "price":"0.22", "size":"24335.62", "side":"SELL", "hash":"895b27530365971e9b9bd5b66c2d42b2a5f691e3", "best_bid":"0.18", "best_ask":"0.19"}], "timestamp":"1789143404537", "event_type":"price_change"}
{"market":"0x876506d8b2bd7a0d3fa4fe18c024eee6e1dd81ee24c26795dadd6cfe4a7b5d0d", "price_changes":[{"asset_id":"63842529068710005716169325380315470359047749786610778647370693404952498013178", "price":"0.78", "size":"24485.62", "side":"BUY", "hash":"67e651220d72bc5cc120feb2493bae24296bcd69", "best_bid":"0.81", "best_ask":"0.82"}, {"asset_id":"2881957189963819690709899387312951271986076905757701114514025622922000576600", "price":"0.22", "size":"24485.62", "side":"SELL", "hash":"e1c9904cdc55987e5622e434ef40fe26580d4c9d", "best_bid":"0.18", "best_ask":"0.19"}], "timestamp":"1789143405979", "event_type":"price_change"}
{"market":"0x876506d8b2bd7a0d3fa4fe18c024eee6e1dd81ee24c26795dadd6cfe4a7b5d0d", "price_changes":[{"asset_id":"63842529068710005716169325380315470359047749786610778647370693404952498013178", "price":"0.01", "size":"1103682.45", "side":"BUY", "hash":"5753856216496a174517f62d75a0893400de9f23", "best_bid":"0.81", "best_ask":"0.82"}, {"asset_id":"2881957189963819690709899387312951271986076905757701114514025622922000576600", "price":"0.99", "size":"1103682.45", "side":"SELL", "hash":"f24ddd4bdd018df603406d5c604a89829ff53be0", "best_bid":"0.18", "best_ask":"0.19"}], "timestamp":"1789143406786", "event_type":"price_change"}
{"market":"0x876506d8b2bd7a0d3fa4fe18c024eee6e1dd81ee24c26795dadd6cfe4a7b5d0d", "price_changes":[{"asset_id":"2881957189963819690709899387312951271986076905757701114514025622922000576600", "price":"0.01", "size":"2253552.07", "side":"BUY", "hash":"c27f565d2da555ebab9fbc6b419b177cd6bf7cd2", "best_bid":"0.18", "best_ask":"0.19"}, {"asset_id":"63842529068710005716169325380315470359047749786610778647370693404952498013178", "price":"0.99", "size":"2253552.07", "side":"SELL", "hash":"4639d96e2eb0b06ef8cdf6c8bc545e533a2ce864", "best_bid":"0.81", "best_ask":"0.82"}], "timestamp":"1789143406883", "event_type":"price_change"}
{"market":"0x876506d8b2bd7a0d3fa4fe18c024eee6e1dd81ee24c26795dadd6cfe4a7b5d0d", "price_changes":[{"asset_id":"63842529068710005716169325380315470359047749786610778647370693404952498013178", "price":"0.01", "size":"1103692.45", "side":"BUY", "hash":"5c01b32485efddbbc2ea4b0dd2546de077acacf6", "best_bid":"0.81", "best_ask":"0.82"}, {"asset_id":"2881957189963819690709899387312951271986076905757701114514025622922000576600", "price":"0.99", "size":"1103692.45", "side":"SELL", "hash":"65eb451cfa749f3b7071fc9ba995742e773e6f42", "best_bid":"0.18", "best_ask":"0.19"}], "timestamp":"1789143407268", "event_type":"price_change"}
{"market":"0x876506d8b2bd7a0d3fa4fe18c024eee6e1dd81ee24c26795dadd6cfe4a7b5d0d", "price_changes":[{"asset_id":"2881957189963819690709899387312951271986076905757701114514025622922000576600", "price":"0.01", "size":"2253562.07", "side":"BUY", "hash":"5b3db070751fa7072ecf292c9ed59a4e0c60f8b5", "best_bid":"0.18", "best_ask":"0.19"}, {"asset_id":"63842529068710005716169325380315470359047749786610778647370693404952498013178", "price":"0.99", "size":"2253562.07", "side":"SELL", "hash":"84af0a05057d792e5de72afdd96ed51e56447d60", "best_bid":"0.81", "best_ask":"0.82"}], "timestamp":"1789143407349", "event_type":"price_change"}
{"market":"0x876506d8b2bd7a0d3fa4fe18c024eee6e1dd81ee24c26795dadd6cfe4a7b5d0d", "price_changes":[{"asset_id":"2881957189963819690709899387312951271986076905757701114514025622922000576600", "price":"0.5", "size":"223.61", "side":"SELL", "hash":"a1554db1ddae8239bf121b3c593d6b05849666f7", "best_bid":"0.18", "best_ask":"0.19"}, {"asset_id":"63842529068710005716169325380315470359047749786610778647370693404952498013178", "price":"0.5", "size":"223.61", "side":"BUY", "hash":"bc63e0218274c2aecee2e7590d279e5f8ff9018f", "best_bid":"0.81", "best_ask":"0.82"}], "timestamp":"1789143417564", "event_type":"price_change"}
{"market":"0x876506d8b2bd7a0d3fa4fe18c024eee6e1dd81ee24c26795dadd6cfe4a7b5d0d", "price_changes":[{"asset_id":"63842529068710005716169325380315470359047749786610778647370693404952498013178", "price":"0.01", "size":"1103682.45", "side":"BUY", "hash":"8682de24df91ced8e52870f54547988385d6c84b", "best_bid":"0.81", "best_ask":"0.82"}, {"asset_id":"2881957189963819690709899387312951271986076905757701114514025622922000576600", "price":"0.99", "size":"1103682.45", "side":"SELL", "hash":"ef4a35466469f1bc7f8182c59face3b88a408e37", "best_bid":"0.18", "best_ask":"0.19"}], "timestamp":"1789143425867", "event_type":"price_change"}
{"market":"0x876506d8b2bd7a0d3fa4fe18c024eee6e1dd81ee24c26795dadd6cfe4a7b5d0d", "price_changes":[{"asset_id":"2881957189963819690709899387312951271986076905757701114514025622922000576600", "price":"0.17", "size":"70168.19", "side":"BUY", "hash":"082c8ad4f37e49dd4be1e2b1e8a678a1d97d7b24", "best_bid":"0.18", "best_ask":"0.19"}, {"asset_id":"63842529068710005716169325380315470359047749786610778647370693404952498013178", "price":"0.83", "size":"70168.19", "side":"SELL", "hash":"a48ef82a13650eb73843c3775d400d7f7755eb0b", "best_bid":"0.81", "best_ask":"0.82"}], "timestamp":"1789143425904", "event_type":"price_change"}
{"market":"0x876506d8b2bd7a0d3fa4fe18c024eee6e1dd81ee24c26795dadd6cfe4a7b5d0d", "price_changes":[{"asset_id":"2881957189963819690709899387312951271986076905757701114514025622922000576600", "price":"0.01", "size":"2253552.07", "side":"BUY", "hash":"501b6844b73e489d3567fb471b6b9a7d9d5ac55f", "best_bid":"0.18", "best_ask":"0.19"}, {"asset_id":"63842529068710005716169325380315470359047749786610778647370693404952498013178", "price":"0.99", "size":"2253552.07", "side":"SELL", "hash":"fdd68649da18632a32162bff9cca93571b8bac96", "best_bid":"0.81", "best_ask":"0.82"}], "timestamp":"1789143425936", "event_type":"price_change"}
{"market":"0x876506d8b2bd7a0d3fa4fe18c024eee6e1dd81ee24c26795dadd6cfe4a7b5d0d", "price_changes":[{"asset_id":"2881957189963819690709899387312951271986076905757701114514025622922000576600", "price":"0.17", "size":"69168.19", "side":"BUY", "hash":"9e00f623f5eee0846393eca2387292184e5df36b", "best_bid":"0.18", "best_ask":"0.19"}, {"asset_id":"63842529068710005716169325380315470359047749786610778647370693404952498013178", "price":"0.83", "size":"69168.19", "side":"SELL", "hash":"04fcdd3384a7c1b2d1bd612bf829a03f9dc68383", "best_bid":"0.81", "best_ask":"0.82"}], "timestamp":"1789143426015", "event_type":"price_change"}
{"market":"0x876506d8b2bd7a0d3fa4fe18c024eee6e1dd81ee24c26795dadd6cfe4a7b5d0d", "price_changes":[{"asset_id":"2881957189963819690709899387312951271986076905757701114514025622922000576600", "price":"0.15", "size":"76814", "side":"BUY", "hash":"5976b7e42dddaae2fc0404ff36c724d20456fc01", "best_bid":"0.18", "best_ask":"0.19"}, {"asset_id":"63842529068710005716169325380315470359047749786610778647370693404952498013178", "price":"0.85", "size":"76814", "side":"SELL", "hash":"dec8c358c3b0990dcc2d341b8ed8af35c86386c7", "best_bid":"0.81", "best_ask":"0.82"}], "timestamp":"1789143426024", "event_type":"price_change"}
{"market":"0x876506d8b2bd7a0d3fa4fe18c024eee6e1dd81ee24c26795dadd6cfe4a7b5d0d", "price_changes":[{"asset_id":"2881957189963819690709899387312951271986076905757701114514025622922000576600", "price":"0.01", "size":"2253592.07", "side":"BUY", "hash":"b4f066fa02ffe951e2e74eae44fc3ba52f30daf3", "best_bid":"0.18", "best_ask":"0.19"}, {"asset_id":"63842529068710005716169325380315470359047749786610778647370693404952498013178", "price":"0.99", "size":"2253592.07", "side":"SELL", "hash":"79961cb86d0827f5490f7a1d91493f8e047d5ee2", "best_bid":"0.81", "best_ask":"0.82"}], "timestamp":"1789143426056", "event_type":"price_change"}
{"market":"0x876506d8b2bd7a0d3fa4fe18c024eee6e1dd81ee24c26795dadd6cfe4a7b5d0d", "price_changes":[{"asset_id":"2881957189963819690709899387312951271986076905757701114514025622922000576600", "price":"0.01", "size":"2253552.07", "side":"BUY", "hash":"3b9a6b423d8c39ffb5d37df54154d3e9c9622ade", "best_bid":"0.18", "best_ask":"0.19"}, {"asset_id":"63842529068710005716169325380315470359047749786610778647370693404952498013178", "price":"0.99", "size":"2253552.07", "side":"SELL", "hash":"f78bb01ed65873b6a545ca1dcff35bde03b7a484", "best_bid":"0.81", "best_ask":"0.82"}], "timestamp":"1789143426102", "event_type":"price_change"}
{"market":"0x876506d8b2bd7a0d3fa4fe18c024eee6e1dd81ee24c26795dadd6cfe4a7b5d0d", "price_changes":[{"asset_id":"63842529068710005716169325380315470359047749786610778647370693404952498013178", "price":"0.01", "size":"1103692.45", "side":"BUY", "hash":"527108e29dec5bd7f2ef8eef9f758545d8543e87", "best_bid":"0.81", "best_ask":"0.82"}, {"asset_id":"2881957189963819690709899387312951271986076905757701114514025622922000576600", "price":"0.99", "size":"1103692.45", "side":"SELL", "hash":"17231c1df492c6f7a723c6f33db1ff92b3a81208", "best_bid":"0.18", "best_ask":"0.19"}], "timestamp":"1789143426443", "event_type":"price_change"}
{"market":"0x876506d8b2bd7a0d3fa4fe18c024eee6e1dd81ee24c26795dadd6cfe4a7b5d0d", "price_changes":[{"asset_id":"2881957189963819690709899387312951271986076905757701114514025622922000576600", "price":"0.01", "size":"2253562.07", "side":"BUY", "hash":"a3fa3d1da3036dbdc955f99ee1a4ea39dfc3e7ab", "best_bid":"0.18", "best_ask":"0.19"}, {"asset_id":"63842529068710005716169325380315470359047749786610778647370693404952498013178", "price":"0.99", "size":"2253562.07", "side":"SELL", "hash":"861edadab2760d7ddd9b21e4c71663aa0f592b3c", "best_bid":"0.81", "best_ask":"0.82"}], "timestamp":"1789143426524", "event_type":"price_change"}
{"market":"0x876506d8b2bd7a0d3fa4fe18c024eee6e1dd81ee24c26795dadd6cfe4a7b5d0d", "price_changes":[{"asset_id":"2881957189963819690709899387312951271986076905757701114514025622922000576600", "price":"0.17", "size":"68968.19", "side":"BUY", "hash":"6ee861926368cce08d971d959fadb453e32da7a4", "best_bid":"0.18", "best_ask":"0.19"}, {"asset_id":"63842529068710005716169325380315470359047749786610778647370693404952498013178", "price":"0.83", "size":"68968.19", "side":"SELL", "hash":"e7cbbacd7314e851f823034b1cdc83eabb795bec", "best_bid":"0.81", "best_ask":"0.82"}], "timestamp":"1789143428725", "event_type":"price_change"}
{"market":"0x876506d8b2bd7a0d3fa4fe18c024eee6e1dd81ee24c26795dadd6cfe4a7b5d0d", "price_changes":[{"asset_id":"2881957189963819690709899387312951271986076905757701114514025622922000576600", "price":"0.4", "size":"227", "side":"SELL", "hash":"9882b83844289ea2c2a7e3bb8b471deed90a0a14", "best_bid":"0.18", "best_ask":"0.19"}, {"asset_id":"63842529068710005716169325380315470359047749786610778647370693404952498013178", "price":"0.6", "size":"227", "side":"BUY", "hash":"4f7c4e15b42cf270f510e4ef01dda540a52af569", "best_bid":"0.81", "best_ask":"0.82"}], "timestamp":"1789143443894", "event_type":"price_change"}
{"market":"0x876506d8b2bd7a0d3fa4fe18c024eee6e1dd81ee24c26795dadd6cfe4a7b5d0d", "price_changes":[{"asset_id":"63842529068710005716169325380315470359047749786610778647370693404952498013178", "price":"0.01", "size":"1103682.45", "side":"BUY", "hash":"198cf28ed614b66140a96c95c89319c569fb5306", "best_bid":"0.81", "best_ask":"0.82"}, {"asset_id":"2881957189963819690709899387312951271986076905757701114514025622922000576600", "price":"0.99", "size":"1103682.45", "side":"SELL", "hash":"b4a117c38043f4bc28e30147845f476ac7024177", "best_bid":"0.18", "best_ask":"0.19"}], "timestamp":"1789143444969", "event_type":"price_change"}
{"market":"0x876506d8b2bd7a0d3fa4fe18c024eee6e1dd81ee24c26795dadd6cfe4a7b5d0d", "price_changes":[{"asset_id":"2881957189963819690709899387312951271986076905757701114514025622922000576600", "price":"0.01", "size":"2253552.07", "side":"BUY", "hash":"42e9d3b526e06510cb0133cdc8b13a4a5e0aaf66", "best_bid":"0.18", "best_ask":"0.19"}, {"asset_id":"63842529068710005716169325380315470359047749786610778647370693404952498013178", "price":"0.99", "size":"2253552.07", "side":"SELL", "hash":"69f100bafa4e4c4bdc0d677e4868b7fa68d77bc9", "best_bid":"0.81", "best_ask":"0.82"}], "timestamp":"1789143445118", "event_type":"price_change"}
{"market":"0x876506d8b2bd7a0d3fa4fe18c024eee6e1dd81ee24c26795dadd6cfe4a7b5d0d", "price_changes":[{"asset_id":"63842529068710005716169325380315470359047749786610778647370693404952498013178", "price":"0.01", "size":"1103692.45", "side":"BUY", "hash":"02dc2247e52b0392a03c25c9f77f41326d5d68b1", "best_bid":"0.81", "best_ask":"0.82"}, {"asset_id":"2881957189963819690709899387312951271986076905757701114514025622922000576600", "price":"0.99", "size":"1103692.45", "side":"SELL", "hash":"bbca458e71b276d9685bd0d4f7eaa83b6b9c8fe3", "best_bid":"0.18", "best_ask":"0.19"}], "timestamp":"1789143445488", "event_type":"price_change"}
{"market":"0x876506d8b2bd7a0d3fa4fe18c024eee6e1dd81ee24c26795dadd6cfe4a7b5d0d", "price_changes":[{"asset_id":"2881957189963819690709899387312951271986076905757701114514025622922000576600", "price":"0.01", "size":"2253562.07", "side":"BUY", "hash":"286a92dc33b83409cb88d22577115758389131aa", "best_bid":"0.18", "best_ask":"0.19"}, {"asset_id":"63842529068710005716169325380315470359047749786610778647370693404952498013178", "price":"0.99", "size":"2253562.07", "side":"SELL", "hash":"74b530d4b8f0fed544b1b5cbdfa30c457d6f94f9", "best_bid":"0.81", "best_ask":"0.82"}], "timestamp":"1789143445571", "event_type":"price_change"}
{"market":"0x876506d8b2bd7a0d3fa4fe18c024eee6e1dd81ee24c26795dadd6cfe4a7b5d0d", "price_changes":[{"asset_id":"2881957189963819690709899387312951271986076905757701114514025622922000576600", "price":"0.17", "size":"69968.19", "side":"BUY", "hash":"fd9302c1cec868b70810dafda2a5996e0b16636c", "best_bid":"0.18", "best_ask":"0.19"}, {"asset_id":"63842529068710005716169325380315470359047749786610778647370693404952498013178", "price":"0.83", "size":"69968.19", "side":"SELL", "hash":"ae74a931e1930170c76030553ecc0031801c971f", "best_bid":"0.81", "best_ask":"0.82"}], "timestamp":"1789143450090", "event_type":"price_change"}
{"market":"0x876506d8b2bd7a0d3fa4fe18c024eee6e1dd81ee24c26795dadd6cfe4a7b5d0d", "price_changes":[{"asset_id":"2881957189963819690709899387312951271986076905757701114514025622922000576600", "price":"0.17", "size":"68968.19", "side":"BUY", "hash":"c92f0f41b21226144268baffa5452df71b918b12", "best_bid":"0.18", "best_ask":"0.19"}, {"asset_id":"63842529068710005716169325380315470359047749786610778647370693404952498013178", "price":"0.83", "size":"68968.19", "side":"SELL", "hash":"809e92a608b9589ad1314e696f69da95c5b3a31c", "best_bid":"0.81", "best_ask":"0.82"}], "timestamp":"1789143450134", "event_type":"price_change"}
{"market":"0x876506d8b2bd7a0d3fa4fe18c024eee6e1dd81ee24c26795dadd6cfe4a7b5d0d", "price_changes":[{"asset_id":"2881957189963819690709899387312951271986076905757701114514025622922000576600", "price":"0.32", "size":"931.09", "side":"SELL", "hash":"62eac8b71196661dcf9ba3684903f987bc134f07", "best_bid":"0.18", "best_ask":"0.19"}, {"asset_id":"63842529068710005716169325380315470359047749786610778647370693404952498013178", "price":"0.68", "size":"931.09", "side":"BUY", "hash":"4d90139cbfd350dbb2527ebf7758d6e422fcf03c", "best_bid":"0.81", "best_ask":"0.82"}], "timestamp":"1789143451643", "event_type":"price_change"}
{"market":"0x876506d8b2bd7a0d3fa4fe18c024eee6e1dd81ee24c26795dadd6cfe4a7b5d0d", "price_changes":[{"asset_id":"63842529068710005716169325380315470359047749786610778647370693404952498013178", "price":"0.01", "size":"1103682.45", "side":"BUY", "hash":"014ff9cc93f6328e1b94d6454f46d778f0311e5a", "best_bid":"0.81", "best_ask":"0.82"}, {"asset_id":"2881957189963819690709899387312951271986076905757701114514025622922000576600", "price":"0.99", "size":"1103682.45", "side":"SELL", "hash":"db74511303a14b6c7de4704293f4ff1cb38ea422", "best_bid":"0.18", "best_ask":"0.19"}], "timestamp":"1789143464148", "event_type":"price_change"}
{"market":"0x876506d8b2bd7a0d3fa4fe18c024eee6e1dd81ee24c26795dadd6cfe4a7b5d0d", "price_changes":[{"asset_id":"2881957189963819690709899387312951271986076905757701114514025622922000576600", "price":"0.01", "size":"2253552.07", "side":"BUY", "hash":"7575b10c995eed3a929b64ac2b7b85f74ce20eba", "best_bid":"0.18", "best_ask":"0.19"}, {"asset_id":"63842529068710005716169325380315470359047749786610778647370693404952498013178", "price":"0.99", "size":"2253552.07", "side":"SELL", "hash":"62bca50d8f78745a7cc458cea75b0c4fd71a9944", "best_bid":"0.81", "best_ask":"0.82"}], "timestamp":"1789143464224", "event_type":"price_change"}
{"market":"0x876506d8b2bd7a0d3fa4fe18c024eee6e1dd81ee24c26795dadd6cfe4a7b5d0d", "price_changes":[{"asset_id":"63842529068710005716169325380315470359047749786610778647370693404952498013178", "price":"0.81", "size":"12813.73", "side":"BUY", "hash":"931a6854a906a96f1a1accbb95167e27e5ff1cff", "best_bid":"0.81", "best_ask":"0.82"}, {"asset_id":"2881957189963819690709899387312951271986076905757701114514025622922000576600", "price":"0.19", "size":"12813.73", "side":"SELL", "hash":"8a25e123ef9ead62ef1878592de4439acf1368fb", "best_bid":"0.18", "best_ask":"0.19"}], "timestamp":"1789143464451", "event_type":"price_change"}
{"market":"0x876506d8b2bd7a0d3fa4fe18c024eee6e1dd81ee24c26795dadd6cfe4a7b5d0d", "price_changes":[{"asset_id":"63842529068710005716169325380315470359047749786610778647370693404952498013178", "price":"0.01", "size":"1103692.45", "side":"BUY", "hash":"1eece08be6a1ca6bbea5e338e89e760f7af0d88c", "best_bid":"0.81", "best_ask":"0.82"}, {"asset_id":"2881957189963819690709899387312951271986076905757701114514025622922000576600", "price":"0.99", "size":"1103692.45", "side":"SELL", "hash":"02ab448c3b136c20723e29cd6425be28dd3feaf6", "best_bid":"0.18", "best_ask":"0.19"}], "timestamp":"1789143464598", "event_type":"price_change"}
{"market":"0x876506d8b2bd7a0d3fa4fe18c024eee6e1dd81ee24c26795dadd6cfe4a7b5d0d", "price_changes":[{"asset_id":"2881957189963819690709899387312951271986076905757701114514025622922000576600", "price":"0.01", "size":"2253562.07", "side":"BUY", "hash":"c8ef198b7fdb01b0f3b4bca8c54b26208a06a63e", "best_bid":"0.18", "best_ask":"0.19"}, {"asset_id":"63842529068710005716169325380315470359047749786610778647370693404952498013178", "price":"0.99", "size":"2253562.07", "side":"SELL", "hash":"096c3c27287d19cdf9b47d0ab190dc51226b69f9", "best_bid":"0.81", "best_ask":"0.82"}], "timestamp":"1789143464675", "event_type":"price_change"}
{"market":"0x876506d8b2bd7a0d3fa4fe18c024eee6e1dd81ee24c26795dadd6cfe4a7b5d0d", "price_changes":[{"asset_id":"63842529068710005716169325380315470359047749786610778647370693404952498013178", "price":"0.81", "size":"13013.73", "side":"BUY", "hash":"fe9d98bb129dc4d1512ca7905597c3d265a94a25", "best_bid":"0.81", "best_ask":"0.82"}, {"asset_id":"2881957189963819690709899387312951271986076905757701114514025622922000576600", "price":"0.19", "size":"13013.73", "side":"SELL", "hash":"59c4d0561a0f77285261fe965b1f5fd3ecbd8869", "best_bid":"0.18", "best_ask":"0.19"}], "timestamp":"1789143464778", "event_type":"price_change"}
{"market":"0x876506d8b2bd7a0d3fa4fe18c024eee6e1dd81ee24c26795dadd6cfe4a7b5d0d", "price_changes":[{"asset_id":"2881957189963819690709899387312951271986076905757701114514025622922000576600", "price":"0.18", "size":"77137.66", "side":"BUY", "hash":"5dd8d146d4b26a85c1e4bad155a44cd9c08802a1", "best_bid":"0.18", "best_ask":"0.19"}, {"asset_id":"63842529068710005716169325380315470359047749786610778647370693404952498013178", "price":"0.82", "size":"77137.66", "side":"SELL", "hash":"3ed6c6acf5117e251db8ee7c53a5c35991281e97", "best_bid":"0.81", "best_ask":"0.82"}], "timestamp":"1789143465111", "event_type":"price_change"}
{"market":"0x876506d8b2bd7a0d3fa4fe18c024eee6e1dd81ee24c26795dadd6cfe4a7b5d0d", "price_changes":[{"asset_id":"63842529068710005716169325380315470359047749786610778647370693404952498013178", "price":"0.82", "size":"77321.16", "side":"SELL", "hash":"68ac4896d6592329020faad543c55bced355f491", "best_bid":"0.81", "best_ask":"0.82"}, {"asset_id":"2881957189963819690709899387312951271986076905757701114514025622922000576600", "price":"0.18", "size":"77321.16", "side":"BUY", "hash":"660ec4f374bfe3fb9c07dcfa38778951a4482894", "best_bid":"0.18", "best_ask":"0.19"}], "timestamp":"1789143465460", "event_type":"price_change"}
{"market":"0x876506d8b2bd7a0d3fa4fe18c024eee6e1dd81ee24c26795dadd6cfe4a7b5d0d", "price_changes":[{"asset_id":"63842529068710005716169325380315470359047749786610778647370693404952498013178", "price":"0.82", "size":"77504.66", "side":"SELL", "hash":"d0dcfe7fee7c2fd1630efa7732ed35988d7310d0", "best_bid":"0.81", "best_ask":"0.82"}, {"asset_id":"2881957189963819690709899387312951271986076905757701114514025622922000576600", "price":"0.18", "size":"77504.66", "side":"BUY", "hash":"2dcd2c305e34541695134eabb83a231a5cbdc306", "best_bid":"0.18", "best_ask":"0.19"}], "timestamp":"1789143465755", "event_type":"price_change"}
{"market":"0x876506d8b2bd7a0d3fa4fe18c024eee6e1dd81ee24c26795dadd6cfe4a7b5d0d", "price_changes":[{"asset_id":"2881957189963819690709899387312951271986076905757701114514025622922000576600", "price":"0.19", "size":"13413.73", "side":"SELL", "hash":"4f4472187d9210ac98bdeb3188d2bef4639c4d33", "best_bid":"0.18", "best_ask":"0.19"}, {"asset_id":"63842529068710005716169325380315470359047749786610778647370693404952498013178", "price":"0.81", "size":"13413.73", "side":"BUY", "hash":"425faa72efe0fb8206c73e14687b5bc01c347346", "best_bid":"0.81", "best_ask":"0.82"}], "timestamp":"1789143466058", "event_type":"price_change"}
{"market":"0x876506d8b2bd7a0d3fa4fe18c024eee6e1dd81ee24c26795dadd6cfe4a7b5d0d", "price_changes":[{"asset_id":"2881957189963819690709899387312951271986076905757701114514025622922000576600", "price":"0.17", "size":"69968.19", "side":"BUY", "hash":"a6abbf1c99d465bdc14f3d836532a916fada4a9d", "best_bid":"0.18", "best_ask":"0.19"}, {"asset_id":"63842529068710005716169325380315470359047749786610778647370693404952498013178", "price":"0.83", "size":"69968.19", "side":"SELL", "hash":"6bcabda43ebff113c185832ced89c4400dac4af9", "best_bid":"0.81", "best_ask":"0.82"}], "timestamp":"1789143475492", "event_type":"price_change"}
{"market":"0x876506d8b2bd7a0d3fa4fe18c024eee6e1dd81ee24c26795dadd6cfe4a7b5d0d", "price_changes":[{"asset_id":"2881957189963819690709899387312951271986076905757701114514025622922000576600", "price":"0.17", "size":"68968.19", "side":"BUY", "hash":"21a5f4f99075d47aae2681269c9f61275b8e127a", "best_bid":"0.18", "best_ask":"0.19"}, {"asset_id":"63842529068710005716169325380315470359047749786610778647370693404952498013178", "price":"0.83", "size":"68968.19", "side":"SELL", "hash":"87857017a50e0e6cba6140e158ccf9ba65bd7f1b", "best_bid":"0.81", "best_ask":"0.82"}], "timestamp":"1789143475526", "event_type":"price_change"}
{"market":"0x876506d8b2bd7a0d3fa4fe18c024eee6e1dd81ee24c26795dadd6cfe4a7b5d0d", "price_changes":[{"asset_id":"63842529068710005716169325380315470359047749786610778647370693404952498013178", "price":"0.74", "size":"2000", "side":"BUY", "hash":"a3c70106c4f019d9c789450676d557542841325c", "best_bid":"0.81", "best_ask":"0.82"}, {"asset_id":"2881957189963819690709899387312951271986076905757701114514025622922000576600", "price":"0.26", "size":"2000", "side":"SELL", "hash":"f14a26198a837b46dc123f4e8a347e4b50329353", "best_bid":"0.18", "best_ask":"0.19"}], "timestamp":"1789143482393", "event_type":"price_change"}
{"market":"0x876506d8b2bd7a0d3fa4fe18c024eee6e1dd81ee24c26795dadd6cfe4a7b5d0d", "price_changes":[{"asset_id":"2881957189963819690709899387312951271986076905757701114514025622922000576600", "price":"0.13", "size":"37050", "side":"BUY", "hash":"f14a26198a837b46dc123f4e8a347e4b50329353", "best_bid":"0.18", "best_ask":"0.19"}, {"asset_id":"63842529068710005716169325380315470359047749786610778647370693404952498013178", "price":"0.87", "size":"37050", "side":"SELL", "hash":"a3c70106c4f019d9c789450676d557542841325c", "best_bid":"0.81", "best_ask":"0.82"}], "timestamp":"1789143482393", "event_type":"price_change"}
{"market":"0x876506d8b2bd7a0d3fa4fe18c024eee6e1dd81ee24c26795dadd6cfe4a7b5d0d", "price_changes":[{"asset_id":"2881957189963819690709899387312951271986076905757701114514025622922000576600", "price":"0.01", "size":"2253362.07", "side":"BUY", "hash":"f14a26198a837b46dc123f4e8a347e4b50329353", "best_bid":"0.18", "best_ask":"0.19"}, {"asset_id":"63842529068710005716169325380315470359047749786610778647370693404952498013178", "price":"0.99", "size":"2253362.07", "side":"SELL", "hash":"a3c70106c4f019d9c789450676d557542841325c", "best_bid":"0.81", "best_ask":"0.82"}], "timestamp":"1789143482393", "event_type":"price_change"}
{"market":"0x876506d8b2bd7a0d3fa4fe18c024eee6e1dd81ee24c26795dadd6cfe4a7b5d0d", "price_changes":[{"asset_id":"2881957189963819690709899387312951271986076905757701114514025622922000576600", "price":"0.1", "size":"40238.51", "side":"BUY", "hash":"f14a26198a837b46dc123f4e8a347e4b50329353", "best_bid":"0.18", "best_ask":"0.19"}, {"asset_id":"63842529068710005716169325380315470359047749786610778647370693404952498013178", "price":"0.9", "size":"40238.51", "side":"SELL", "hash":"a3c70106c4f019d9c789450676d557542841325c", "best_bid":"0.81", "best_ask":"0.82"}], "timestamp":"1789143482393", "event_type":"price_change"}
{"market":"0x876506d8b2bd7a0d3fa4fe18c024eee6e1dd81ee24c26795dadd6cfe4a7b5d0d", "price_changes":[{"asset_id":"63842529068710005716169325380315470359047749786610778647370693404952498013178", "price":"0.56", "size":"0", "side":"BUY", "hash":"a3c70106c4f019d9c789450676d557542841325c", "best_bid":"0.81", "best_ask":"0.82"}, {"asset_id":"2881957189963819690709899387312951271986076905757701114514025622922000576600", "price":"0.44", "size":"0", "side":"SELL", "hash":"f14a26198a837b46dc123f4e8a347e4b50329353", "best_bid":"0.18", "best_ask":"0.19"}], "timestamp":"1789143482393", "event_type":"price_change"}
{"market":"0x876506d8b2bd7a0d3fa4fe18c024eee6e1dd81ee24c26795dadd6cfe4a7b5d0d", "price_changes":[{"asset_id":"63842529068710005716169325380315470359047749786610778647370693404952498013178", "price":"0.71", "size":"6719.73", "side":"BUY", "hash":"a3c70106c4f019d9c789450676d557542841325c", "best_bid":"0.81", "best_ask":"0.82"}, {"asset_id":"2881957189963819690709899387312951271986076905757701114514025622922000576600", "price":"0.29", "size":"6719.73", "side":"SELL", "hash":"f14a26198a837b46dc123f4e8a347e4b50329353", "best_bid":"0.18", "best_ask":"0.19"}], "timestamp":"1789143482393", "event_type":"price_change"}
{"market":"0x876506d8b2bd7a0d3fa4fe18c024eee6e1dd81ee24c26795dadd6cfe4a7b5d0d", "price_changes":[{"asset_id":"2881957189963819690709899387312951271986076905757701114514025622922000576600", "price":"0.05", "size":"31622", "side":"BUY", "hash":"f14a26198a837b46dc123f4e8a347e4b50329353", "best_bid":"0.18", "best_ask":"0.19"}, {"asset_id":"63842529068710005716169325380315470359047749786610778647370693404952498013178", "price":"0.95", "size":"31622", "side":"SELL", "hash":"a3c70106c4f019d9c789450676d557542841325c", "best_bid":"0.81", "best_ask":"0.82"}], "timestamp":"1789143482393", "event_type":"price_change"}
{"market":"0x876506d8b2bd7a0d3fa4fe18c024eee6e1dd81ee24c26795dadd6cfe4a7b5d0d", "price_changes":[{"asset_id":"63842529068710005716169325380315470359047749786610778647370693404952498013178", "price":"0.66", "size":"2284.42", "side":"BUY", "hash":"a3c70106c4f019d9c789450676d557542841325c", "best_bid":"0.81", "best_ask":"0.82"}, {"asset_id":"2881957189963819690709899387312951271986076905757701114514025622922000576600", "price":"0.34", "size":"2284.42", "side":"SELL", "hash":"f14a26198a837b46dc123f4e8a347e4b50329353", "best_bid":"0.18", "best_ask":"0.19"}], "timestamp":"1789143482393", "event_type":"price_change"}
{"market":"0x876506d8b2bd7a0d3fa4fe18c024eee6e1dd81ee24c26795dadd6cfe4a7b5d0d", "price_changes":[{"asset_id":"63842529068710005716169325380315470359047749786610778647370693404952498013178", "price":"0.01", "size":"1103682.45", "side":"BUY", "hash":"4f199c268c7ac85e75126e1f32525746b7df2231", "best_bid":"0.81", "best_ask":"0.82"}, {"asset_id":"2881957189963819690709899387312951271986076905757701114514025622922000576600", "price":"0.99", "size":"1103682.45", "side":"SELL", "hash":"8f2bf3010040d6ba69d55977a3382b0a0f34db17", "best_bid":"0.18", "best_ask":"0.19"}], "timestamp":"1789143483187", "event_type":"price_change"}
{"market":"0x876506d8b2bd7a0d3fa4fe18c024eee6e1dd81ee24c26795dadd6cfe4a7b5d0d", "price_changes":[{"asset_id":"2881957189963819690709899387312951271986076905757701114514025622922000576600", "price":"0.01", "size":"2253352.07", "side":"BUY", "hash":"5e6684c0a3310823a714b21c6ed7360bcec18aca", "best_bid":"0.18", "best_ask":"0.19"}, {"asset_id":"63842529068710005716169325380315470359047749786610778647370693404952498013178", "price":"0.99", "size":"2253352.07", "side":"SELL", "hash":"f48d6c2241f18ebd84e269cf3e2c7c03235d8501", "best_bid":"0.81", "best_ask":"0.82"}], "timestamp":"1789143483259", "event_type":"price_change"}
{"market":"0x876506d8b2bd7a0d3fa4fe18c024eee6e1dd81ee24c26795dadd6cfe4a7b5d0d", "price_changes":[{"asset_id":"63842529068710005716169325380315470359047749786610778647370693404952498013178", "price":"0.01", "size":"1103692.45", "side":"BUY", "hash":"936ef67cf345a6cf46b427e19c4dcd77d01298ca", "best_bid":"0.81", "best_ask":"0.82"}, {"asset_id":"2881957189963819690709899387312951271986076905757701114514025622922000576600", "price":"0.99", "size":"1103692.45", "side":"SELL", "hash":"adff2067ee00ba9e54f79c5ec019ff81ed24e005", "best_bid":"0.18", "best_ask":"0.19"}], "timestamp":"1789143483655", "event_type":"price_change"}
{"market":"0x876506d8b2bd7a0d3fa4fe18c024eee6e1dd81ee24c26795dadd6cfe4a7b5d0d", "price_changes":[{"asset_id":"2881957189963819690709899387312951271986076905757701114514025622922000576600", "price":"0.01", "size":"2253362.07", "side":"BUY", "hash":"0da942ff0aa98b831c81de535966be04741272f6", "best_bid":"0.18", "best_ask":"0.19"}, {"asset_id":"63842529068710005716169325380315470359047749786610778647370693404952498013178", "price":"0.99", "size":"2253362.07", "side":"SELL", "hash":"871c9bd4a38d529a2163ad288c04bdc88c85b235", "best_bid":"0.81", "best_ask":"0.82"}], "timestamp":"1789143483736", "event_type":"price_change"}
{"market":"0x876506d8b2bd7a0d3fa4fe18c024eee6e1dd81ee24c26795dadd6cfe4a7b5d0d", "price_changes":[{"asset_id":"63842529068710005716169325380315470359047749786610778647370693404952498013178", "price":"0.81", "size":"13613.73", "side":"BUY", "hash":"1d0db561c3593e9373830b46bf7ff32a8fe405d0", "best_bid":"0.81", "best_ask":"0.82"}, {"asset_id":"2881957189963819690709899387312951271986076905757701114514025622922000576600", "price":"0.19", "size":"13613.73", "side":"SELL", "hash":"6e6c28fe425149e87683a41783c7bcb85255e071", "best_bid":"0.18", "best_ask":"0.19"}], "timestamp":"1789143489652", "event_type":"price_change"}
{"market":"0x876506d8b2bd7a0d3fa4fe18c024eee6e1dd81ee24c26795dadd6cfe4a7b5d0d", "price_changes":[{"asset_id":"2881957189963819690709899387312951271986076905757701114514025622922000576600", "price":"0.18", "size":"77704.66", "side":"BUY", "hash":"ffae92f4b3e5638a4c1443c5497dc81ea766882e", "best_bid":"0.18", "best_ask":"0.19"}, {"asset_id":"63842529068710005716169325380315470359047749786610778647370693404952498013178", "price":"0.82", "size":"77704.66", "side":"SELL", "hash":"fd350e55ed68ffe3afadbd38a1bec0552a799266", "best_bid":"0.81", "best_ask":"0.82"}], "timestamp":"1789143489653", "event_type":"price_change"}
{"market":"0x876506d8b2bd7a0d3fa4fe18c024eee6e1dd81ee24c26795dadd6cfe4a7b5d0d", "price_changes":[{"asset_id":"2881957189963819690709899387312951271986076905757701114514025622922000576600", "price":"0.17", "size":"69968.19", "side":"BUY", "hash":"f8c02fac556753c32d2c9274cfbaf041e2ca7a33", "best_bid":"0.18", "best_ask":"0.19"}, {"asset_id":"63842529068710005716169325380315470359047749786610778647370693404952498013178", "price":"0.83", "size":"69968.19", "side":"SELL", "hash":"b83bc2f8e19c4ff2838d495de0c297361d9ee952", "best_bid":"0.81", "best_ask":"0.82"}], "timestamp":"1789143495596", "event_type":"price_change"}
{"market":"0x876506d8b2bd7a0d3fa4fe18c024eee6e1dd81ee24c26795dadd6cfe4a7b5d0d", "price_changes":[{"asset_id":"2881957189963819690709899387312951271986076905757701114514025622922000576600", "price":"0.17", "size":"68968.19", "side":"BUY", "hash":"31df9477bee75f0ffd2d568f9605af53ba1affb1", "best_bid":"0.18", "best_ask":"0.19"}, {"asset_id":"63842529068710005716169325380315470359047749786610778647370693404952498013178", "price":"0.83", "size":"68968.19", "side":"SELL", "hash":"b78a0efdacfce95067ed4198a392aeeb28256d18", "best_bid":"0.81", "best_ask":"0.82"}], "timestamp":"1789143495686", "event_type":"price_change"}
{"market":"0x876506d8b2bd7a0d3fa4fe18c024eee6e1dd81ee24c26795dadd6cfe4a7b5d0d", "price_changes":[{"asset_id":"63842529068710005716169325380315470359047749786610778647370693404952498013178", "price":"0.01", "size":"1103682.45", "side":"BUY", "hash":"0aa3ccd2245338e3147e6df1140e46dc351bdb85", "best_bid":"0.81", "best_ask":"0.82"}, {"asset_id":"2881957189963819690709899387312951271986076905757701114514025622922000576600", "price":"0.99", "size":"1103682.45", "side":"SELL", "hash":"b2964ad4f274234682321bcbec783f6599e98f5e", "best_bid":"0.18", "best_ask":"0.19"}], "timestamp":"1789143502186", "event_type":"price_change"}
{"market":"0x876506d8b2bd7a0d3fa4fe18c024eee6e1dd81ee24c26795dadd6cfe4a7b5d0d", "price_changes":[{"asset_id":"2881957189963819690709899387312951271986076905757701114514025622922000576600", "price":"0.01", "size":"2253352.07", "side":"BUY", "hash":"b5018fde608135e609d9f32577379e7d174a49a9", "best_bid":"0.18", "best_ask":"0.19"}, {"asset_id":"63842529068710005716169325380315470359047749786610778647370693404952498013178", "price":"0.99", "size":"2253352.07", "side":"SELL", "hash":"f7a753b7fb6be1bfe3f0bf97b6de831af0c1611d", "best_bid":"0.81", "best_ask":"0.82"}], "timestamp":"1789143502262", "event_type":"price_change"}
{"market":"0x876506d8b2bd7a0d3fa4fe18c024eee6e1dd81ee24c26795dadd6cfe4a7b5d0d", "price_changes":[{"asset_id":"2881957189963819690709899387312951271986076905757701114514025622922000576600", "price":"0.02", "size":"57320.6", "side":"BUY", "hash":"109bfc4a67eb803dd11d5c4d30845a16934a0745", "best_bid":"0.18", "best_ask":"0.19"}, {"asset_id":"63842529068710005716169325380315470359047749786610778647370693404952498013178", "price":"0.98", "size":"57320.6", "side":"SELL", "hash":"d65a86aefb55b824a1c2455731b165da98119ff6", "best_bid":"0.81", "best_ask":"0.82"}], "timestamp":"1789143502507", "event_type":"price_change"}
{"market":"0x876506d8b2bd7a0d3fa4fe18c024eee6e1dd81ee24c26795dadd6cfe4a7b5d0d", "price_changes":[{"asset_id":"63842529068710005716169325380315470359047749786610778647370693404952498013178", "price":"0.01", "size":"1103692.45", "side":"BUY", "hash":"97d60b1906d5fea0c93c080c415af1afa341416a", "best_bid":"0.81", "best_ask":"0.82"}, {"asset_id":"2881957189963819690709899387312951271986076905757701114514025622922000576600", "price":"0.99", "size":"1103692.45", "side":"SELL", "hash":"f58de8ffaf50aa5d0cf2e7a6673fcd727360fa01", "best_bid":"0.18", "best_ask":"0.19"}], "timestamp":"1789143502628", "event_type":"price_change"}
{"market":"0x876506d8b2bd7a0d3fa4fe18c024eee6e1dd81ee24c26795dadd6cfe4a7b5d0d", "price_changes":[{"asset_id":"2881957189963819690709899387312951271986076905757701114514025622922000576600", "price":"0.01", "size":"2253362.07", "side":"BUY", "hash":"b1f23d9683862f80d395c48367aaaaaa8706591a", "best_bid":"0.18", "best_ask":"0.19"}, {"asset_id":"63842529068710005716169325380315470359047749786610778647370693404952498013178", "price":"0.99", "size":"2253362.07", "side":"SELL", "hash":"8d96cde640201006ee620a4d9972eb138613e668", "best_bid":"0.81", "best_ask":"0.82"}], "timestamp":"1789143502711", "event_type":"price_change"}
{"market":"0x876506d8b2bd7a0d3fa4fe18c024eee6e1dd81ee24c26795dadd6cfe4a7b5d0d", "price_changes":[{"asset_id":"2881957189963819690709899387312951271986076905757701114514025622922000576600", "price":"0.17", "size":"68733.19", "side":"BUY", "hash":"8add11d062c4928a0d33ed448967d632beb1d653", "best_bid":"0.18", "best_ask":"0.19"}, {"asset_id":"63842529068710005716169325380315470359047749786610778647370693404952498013178", "price":"0.83", "size":"68733.19", "side":"SELL", "hash":"b3f161cee0d0deec59a9ccbf6355f06dff0455d7", "best_bid":"0.81", "best_ask":"0.82"}], "timestamp":"1789143507903", "event_type":"price_change"}
{"market":"0x876506d8b2bd7a0d3fa4fe18c024eee6e1dd81ee24c26795dadd6cfe4a7b5d0d", "price_changes":[{"asset_id":"2881957189963819690709899387312951271986076905757701114514025622922000576600", "price":"0.02", "size":"57280.6", "side":"BUY", "hash":"a2f70b43aced0a34c9d7901b721374e6bb13a594", "best_bid":"0.18", "best_ask":"0.19"}, {"asset_id":"63842529068710005716169325380315470359047749786610778647370693404952498013178", "price":"0.98", "size":"57280.6", "side":"SELL", "hash":"aedb59bbd8a059a4f0db36f6f2c5d61ff9c0160e", "best_bid":"0.81", "best_ask":"0.82"}], "timestamp":"1789143507939", "event_type":"price_change"}
{"market":"0x876506d8b2bd7a0d3fa4fe18c024eee6e1dd81ee24c26795dadd6cfe4a7b5d0d", "price_changes":[{"asset_id":"2881957189963819690709899387312951271986076905757701114514025622922000576600", "price":"0.17", "size":"68968.19", "side":"BUY", "hash":"a5465e75b22faa20ed1d461ce79991f2ed95255e", "best_bid":"0.18", "best_ask":"0.19"}, {"asset_id":"63842529068710005716169325380315470359047749786610778647370693404952498013178", "price":"0.83", "size":"68968.19", "side":"SELL", "hash":"ef194a902efc9dc4fc2d0be8a74d075cb5444267", "best_bid":"0.81", "best_ask":"0.82"}], "timestamp":"1789143507940", "event_type":"price_change"}
{"market":"0x876506d8b2bd7a0d3fa4fe18c024eee6e1dd81ee24c26795dadd6cfe4a7b5d0d", "price_changes":[{"asset_id":"63842529068710005716169325380315470359047749786610778647370693404952498013178", "price":"0.82", "size":"76497.56", "side":"SELL", "hash":"40518266b7aa765dba38ed6bedf82d18d33bfd2b", "best_bid":"0.81", "best_ask":"0.82"}, {"asset_id":"2881957189963819690709899387312951271986076905757701114514025622922000576600", "price":"0.18", "size":"76497.56", "side":"BUY", "hash":"a1cb0729ad55af7d24e7932fee5f8283d8b1a092", "best_bid":"0.18", "best_ask":"0.19"}], "timestamp":"1789143511071", "event_type":"price_change"}
{"market":"0x876506d8b2bd7a0d3fa4fe18c024eee6e1dd81ee24c26795dadd6cfe4a7b5d0d", "asset_id":"63842529068710005716169325380315470359047749786610778647370693404952498013178", "bids":[{"price":"0.01", "size":"1103692.45"}, {"price":"0.02", "size":"3406.6"}, {"price":"0.03", "size":"70623.04"}, {"price":"0.04", "size":"60500"}, {"price":"0.05", "size":"30250"}, {"price":"0.06", "size":"39427.78"}, {"price":"0.07", "size":"35317.5"}, {"price":"0.08", "size":"10010"}, {"price":"0.09", "size":"10245.62"}, {"price":"0.1", "size":"10295"}, {"price":"0.12", "size":"18005.41"}, {"price":"0.14", "size":"5"}, {"price":"0.15", "size":"174.38"}, {"price":"0.16", "size":"100"}, {"price":"0.17", "size":"12765.59"}, {"price":"0.18", "size":"5"}, {"price":"0.2", "size":"310"}, {"price":"0.21", "size":"5"}, {"price":"0.22", "size":"6592.61"}, {"price":"0.23", "size":"9264.52"}, {"price":"0.24", "size":"30007"}, {"price":"0.26", "size":"20"}, {"price":"0.27", "size":"5950.21"}, {"price":"0.28", "size":"1051.66"}, {"price":"0.29", "size":"200"}, {"price":"0.3", "size":"1375"}, {"price":"0.31", "size":"300"}, {"price":"0.32", "size":"3834.18"}, {"price":"0.33", "size":"300"}, {"price":"0.34", "size":"20299.98"}, {"price":"0.35", "size":"100"}, {"price":"0.36", "size":"100"}, {"price":"0.37", "size":"2878.72"}, {"price":"0.38", "size":"110"}, {"price":"0.39", "size":"100"}, {"price":"0.4", "size":"100"}, {"price":"0.42", "size":"2465.92"}, {"price":"0.45", "size":"400"}, {"price":"0.46", "size":"1000"}, {"price":"0.47", "size":"2200"}, {"price":"0.48", "size":"220"}, {"price":"0.49", "size":"1000"}, {"price":"0.5", "size":"223.61"}, {"price":"0.51", "size":"750"}, {"price":"0.52", "size":"10000.01"}, {"price":"0.53", "size":"10000"}, {"price":"0.54", "size":"10075"}, {"price":"0.55", "size":"4024.99"}, {"price":"0.59", "size":"50"}, {"price":"0.6", "size":"227"}, {"price":"0.61", "size":"2409"}, {"price":"0.62", "size":"4205"}, {"price":"0.63", "size":"50010"}, {"price":"0.64", "size":"2020"}, {"price":"0.65", "size":"1015.3"}, {"price":"0.66", "size":"2284.42"}, {"price":"0.67", "size":"3200"}, {"price":"0.68", "size":"931.09"}, {"price":"0.69", "size":"2501.7"}, {"price":"0.7", "size":"3060"}, {"price":"0.71", "size":"6719.73"}, {"price":"0.72", "size":"1500"}, {"price":"0.73", "size":"11.14"}, {"price":"0.74", "size":"2000"}, {"price":"0.75", "size":"14018"}, {"price":"0.76", "size":"39432.99"}, {"price":"0.77", "size":"377789.56"}, {"price":"0.78", "size":"24485.62"}, {"price":"0.79", "size":"121320.12"}, {"price":"0.8", "size":"625637.04"}, {"price":"0.81", "size":"13613.73"}], "asks":[{"price":"0.99", "size":"2253362.07"}, {"price":"0.98", "size":"57280.6"}, {"price":"0.97", "size":"95648.36"}, {"price":"0.96", "size":"64750"}, {"price":"0.95", "size":"31622"}, {"price":"0.94", "size":"46340.08"}, {"price":"0.93", "size":"34691.41"}, {"price":"0.92", "size":"33019"}, {"price":"0.91", "size":"44610"}, {"price":"0.9", "size":"40238.51"}, {"price":"0.89", "size":"78583.18"}, {"price":"0.88", "size":"58110"}, {"price":"0.87", "size":"37050"}, {"price":"0.86", "size":"46773.03"}, {"price":"0.85", "size":"76814"}, {"price":"0.84", "size":"41869.54"}, {"price":"0.83", "size":"68968.19"}, {"price":"0.82", "size":"76497.56"}], "hash":"40518266b7aa765dba38ed6bedf82d18d33bfd2b", "timestamp":"1789143511071", "event_type":"book"}
{"market":"0x876506d8b2bd7a0d3fa4fe18c024eee6e1dd81ee24c26795dadd6cfe4a7b5d0d", "asset_id":"63842529068710005716169325380315470359047749786610778647370693404952498013178", "price":"0.82", "size":"1207.097561", "fee_rate_bps":"0", "side":"BUY", "timestamp":"1789143511098", "event_type":"last_trade_price", "transaction_hash":"0xecc91f3c8e96ecfcf54828202828d92b15d70af443c2fcf256613f54a763e430"}
{"market":"0x876506d8b2bd7a0d3fa4fe18c024eee6e1dd81ee24c26795dadd6cfe4a7b5d0d", "price_changes":[{"asset_id":"2881957189963819690709899387312951271986076905757701114514025622922000576600", "price":"0.17", "size":"68733.19", "side":"BUY", "hash":"91284c69d527761f97a2a1174288bb900bf77e15", "best_bid":"0.18", "best_ask":"0.19"}, {"asset_id":"63842529068710005716169325380315470359047749786610778647370693404952498013178", "price":"0.83", "size":"68733.19", "side":"SELL", "hash":"f311acc2eb577c203a38ffefa54548ef2870c2d7", "best_bid":"0.81", "best_ask":"0.82"}], "timestamp":"1789143511142", "event_type":"price_change"}
{"market":"0x876506d8b2bd7a0d3fa4fe18c024eee6e1dd81ee24c26795dadd6cfe4a7b5d0d", "price_changes":[{"asset_id":"2881957189963819690709899387312951271986076905757701114514025622922000576600", "price":"0.17", "size":"68498.19", "side":"BUY", "hash":"f6a6a5cca949fddd190d4947784ce0ad1eec778a", "best_bid":"0.18", "best_ask":"0.19"}, {"asset_id":"63842529068710005716169325380315470359047749786610778647370693404952498013178", "price":"0.83", "size":"68498.19", "side":"SELL", "hash":"18b019c15e50281d51b5463634f05edb62d6effa", "best_bid":"0.81", "best_ask":"0.82"}], "timestamp":"1789143511142", "event_type":"price_change"}
{"market":"0x876506d8b2bd7a0d3fa4fe18c024eee6e1dd81ee24c26795dadd6cfe4a7b5d0d", "price_changes":[{"asset_id":"2881957189963819690709899387312951271986076905757701114514025622922000576600", "price":"0.16", "size":"36695.54", "side":"BUY", "hash":"1cd040bce81ca3ffd565fe1588866fe927cf7fcb", "best_bid":"0.18", "best_ask":"0.19"}, {"asset_id":"63842529068710005716169325380315470359047749786610778647370693404952498013178", "price":"0.84", "size":"36695.54", "side":"SELL", "hash":"a07932c67f2b4e6a8a84964155fb9950e57c4040", "best_bid":"0.81", "best_ask":"0.82"}], "timestamp":"1789143511143", "event_type":"price_change"}
{"market":"0x876506d8b2bd7a0d3fa4fe18c024eee6e1dd81ee24c26795dadd6cfe4a7b5d0d", "price_changes":[{"asset_id":"63842529068710005716169325380315470359047749786610778647370693404952498013178", "price":"0.79", "size":"120272.12", "side":"BUY", "hash":"c27e8b0d358c48df6ef05a950f044e30deb0baff", "best_bid":"0.81", "best_ask":"0.82"}, {"asset_id":"2881957189963819690709899387312951271986076905757701114514025622922000576600", "price":"0.21", "size":"120272.12", "side":"SELL", "hash":"25b0674771f79f9812af2bce85381d2e265bfc4d", "best_bid":"0.18", "best_ask":"0.19"}], "timestamp":"1789143511147", "event_type":"price_change"}
{"market":"0x876506d8b2bd7a0d3fa4fe18c024eee6e1dd81ee24c26795dadd6cfe4a7b5d0d", "price_changes":[{"asset_id":"2881957189963819690709899387312951271986076905757701114514025622922000576600", "price":"0.05", "size":"31632", "side":"BUY", "hash":"a237c7b1a55fed78eebd555f6c0ba293d32512e8", "best_bid":"0.18", "best_ask":"0.19"}, {"asset_id":"63842529068710005716169325380315470359047749786610778647370693404952498013178", "price":"0.95", "size":"31632", "side":"SELL", "hash":"d2c1497527ec3b15aefe4988c33bcdaf984f3556", "best_bid":"0.81", "best_ask":"0.82"}], "timestamp":"1789143511175", "event_type":"price_change"}
{"market":"0x876506d8b2bd7a0d3fa4fe18c024eee6e1dd81ee24c26795dadd6cfe4a7b5d0d", "price_changes":[{"asset_id":"63842529068710005716169325380315470359047749786610778647370693404952498013178", "price":"0.62", "size":"4215", "side":"BUY", "hash":"e2aed0ec7e77782d37c7740c102ff5b1430c7a8a", "best_bid":"0.81", "best_ask":"0.82"}, {"asset_id":"2881957189963819690709899387312951271986076905757701114514025622922000576600", "price":"0.38", "size":"4215", "side":"SELL", "hash":"caac6df0386f39f4f67a9d9c24b6fdf3903d9c38", "best_bid":"0.18", "best_ask":"0.19"}], "timestamp":"1789143511176", "event_type":"price_change"}
{"market":"0x876506d8b2bd7a0d3fa4fe18c024eee6e1dd81ee24c26795dadd6cfe4a7b5d0d", "price_changes":[{"asset_id":"63842529068710005716169325380315470359047749786610778647370693404952498013178", "price":"0.81", "size":"13413.73", "side":"BUY", "hash":"c6da25a024698a1a4cc169565639202215ca8bc2", "best_bid":"0.81", "best_ask":"0.82"}, {"asset_id":"2881957189963819690709899387312951271986076905757701114514025622922000576600", "price":"0.19", "size":"13413.73", "side":"SELL", "hash":"5954602bd0603acd2e71b7fdb14c00417d65459c", "best_bid":"0.18", "best_ask":"0.19"}], "timestamp":"1789143511198", "event_type":"price_change"}
{"market":"0x876506d8b2bd7a0d3fa4fe18c024eee6e1dd81ee24c26795dadd6cfe4a7b5d0d", "price_changes":[{"asset_id":"2881957189963819690709899387312951271986076905757701114514025622922000576600", "price":"0.18", "size":"76297.56", "side":"BUY", "hash":"5954602bd0603acd2e71b7fdb14c00417d65459c", "best_bid":"0.18", "best_ask":"0.19"}, {"asset_id":"63842529068710005716169325380315470359047749786610778647370693404952498013178", "price":"0.82", "size":"76297.56", "side":"SELL", "hash":"c6da25a024698a1a4cc169565639202215ca8bc2", "best_bid":"0.81", "best_ask":"0.82"}], "timestamp":"1789143511198", "event_type":"price_change"}
{"market":"0x876506d8b2bd7a0d3fa4fe18c024eee6e1dd81ee24c26795dadd6cfe4a7b5d0d", "price_changes":[{"asset_id":"2881957189963819690709899387312951271986076905757701114514025622922000576600", "price":"0.17", "size":"68733.19", "side":"BUY", "hash":"642cae24bf5e9679e1cc3bd4e9ad6170fbbbceaf", "best_bid":"0.18", "best_ask":"0.19"}, {"asset_id":"63842529068710005716169325380315470359047749786610778647370693404952498013178", "price":"0.83", "size":"68733.19", "side":"SELL", "hash":"58b1777183eb7f6ffa8cc1fb5a4e650113ed5478", "best_bid":"0.81", "best_ask":"0.82"}], "timestamp":"1789143511199", "event_type":"price_change"}
{"market":"0x876506d8b2bd7a0d3fa4fe18c024eee6e1dd81ee24c26795dadd6cfe4a7b5d0d", "price_changes":[{"asset_id":"2881957189963819690709899387312951271986076905757701114514025622922000576600", "price":"0.17", "size":"68968.19", "side":"BUY", "hash":"5aa129cb8d316ca04a2be9f892ab3bbac047bb8a", "best_bid":"0.18", "best_ask":"0.19"}, {"asset_id":"63842529068710005716169325380315470359047749786610778647370693404952498013178", "price":"0.83", "size":"68968.19", "side":"SELL", "hash":"6e83a83ea3c35cffa9e11f561456e93ca24ffd9c", "best_bid":"0.81", "best_ask":"0.82"}], "timestamp":"1789143511200", "event_type":"price_change"}
{"market":"0x876506d8b2bd7a0d3fa4fe18c024eee6e1dd81ee24c26795dadd6cfe4a7b5d0d", "price_changes":[{"asset_id":"63842529068710005716169325380315470359047749786610778647370693404952498013178", "price":"0.79", "size":"121320.12", "side":"BUY", "hash":"04608d9c3f49a53e6c18c7a38e2577d4126bea27", "best_bid":"0.81", "best_ask":"0.82"}, {"asset_id":"2881957189963819690709899387312951271986076905757701114514025622922000576600", "price":"0.21", "size":"121320.12", "side":"SELL", "hash":"8ffa8542dc8decc316e11fac36b9d8735d25129e", "best_bid":"0.18", "best_ask":"0.19"}], "timestamp":"1789143511205", "event_type":"price_change"}
{"market":"0x876506d8b2bd7a0d3fa4fe18c024eee6e1dd81ee24c26795dadd6cfe4a7b5d0d", "price_changes":[{"asset_id":"63842529068710005716169325380315470359047749786610778647370693404952498013178", "price":"0.62", "size":"4225", "side":"BUY", "hash":"9584962831e2329e6b9d5a7aee30e27be8b35985", "best_bid":"0.81", "best_ask":"0.82"}, {"asset_id":"2881957189963819690709899387312951271986076905757701114514025622922000576600", "price":"0.38", "size":"4225", "side":"SELL", "hash":"36bb4a7efafa75036908e584ccb62005f06804b2", "best_bid":"0.18", "best_ask":"0.19"}], "timestamp":"1789143511234", "event_type":"price_change"}
{"market":"0x876506d8b2bd7a0d3fa4fe18c024eee6e1dd81ee24c26795dadd6cfe4a7b5d0d", "price_changes":[{"asset_id":"2881957189963819690709899387312951271986076905757701114514025622922000576600", "price":"0.05", "size":"31642", "side":"BUY", "hash":"fe538c91bc5a730c33459fe23d047e6624929245", "best_bid":"0.18", "best_ask":"0.19"}, {"asset_id":"63842529068710005716169325380315470359047749786610778647370693404952498013178", "price":"0.95", "size":"31642", "side":"SELL", "hash":"e3d80afbd2f6dc4339de955802bc4c638fa50e2d", "best_bid":"0.81", "best_ask":"0.82"}], "timestamp":"1789143511243", "event_type":"price_change"}
{"market":"0x876506d8b2bd7a0d3fa4fe18c024eee6e1dd81ee24c26795dadd6cfe4a7b5d0d", "price_changes":[{"asset_id":"63842529068710005716169325380315470359047749786610778647370693404952498013178", "price":"0.81", "size":"13613.73", "side":"BUY", "hash":"e87a22815559a3551c824833dd7a5f0e8f3c4aa9", "best_bid":"0.81", "best_ask":"0.82"}, {"asset_id":"2881957189963819690709899387312951271986076905757701114514025622922000576600", "price":"0.19", "size":"13613.73", "side":"SELL", "hash":"9502781b3bcd7c0da616b3d2101f335ebaa247fe", "best_bid":"0.18", "best_ask":"0.19"}], "timestamp":"1789143511349", "event_type":"price_change"}
{"market":"0x876506d8b2bd7a0d3fa4fe18c024eee6e1dd81ee24c26795dadd6cfe4a7b5d0d", "price_changes":[{"asset_id":"2881957189963819690709899387312951271986076905757701114514025622922000576600", "price":"0.18", "size":"76497.56", "side":"BUY", "hash":"7ef6f56048add236993cb36c36e1a6dda846adce", "best_bid":"0.18", "best_ask":"0.19"}, {"asset_id":"63842529068710005716169325380315470359047749786610778647370693404952498013178", "price":"0.82", "size":"76497.56", "side":"SELL", "hash":"abbbeaf99f502ef0deb9a8be0ad7143e6306bff0", "best_bid":"0.81", "best_ask":"0.82"}], "timestamp":"1789143511350", "event_type":"price_change"}
{"market":"0x876506d8b2bd7a0d3fa4fe18c024eee6e1dd81ee24c26795dadd6cfe4a7b5d0d", "price_changes":[{"asset_id":"2881957189963819690709899387312951271986076905757701114514025622922000576600", "price":"0.16", "size":"41869.54", "side":"BUY", "hash":"d5ceece6e93c0dd42f9fd0757294034556cc4c6e", "best_bid":"0.18", "best_ask":"0.19"}, {"asset_id":"63842529068710005716169325380315470359047749786610778647370693404952498013178", "price":"0.84", "size":"41869.54", "side":"SELL", "hash":"35bd46541a3942a89313b2cccd015c83ac4925f0", "best_bid":"0.81", "best_ask":"0.82"}], "timestamp":"1789143511351", "event_type":"price_change"}
{"market":"0x876506d8b2bd7a0d3fa4fe18c024eee6e1dd81ee24c26795dadd6cfe4a7b5d0d", "price_changes":[{"asset_id":"63842529068710005716169325380315470359047749786610778647370693404952498013178", "price":"0.82", "size":"76376.97", "side":"SELL", "hash":"ddd735aa7df38d960030dc709f1779a1ac98f7fb", "best_bid":"0.81", "best_ask":"0.82"}, {"asset_id":"2881957189963819690709899387312951271986076905757701114514025622922000576600", "price":"0.18", "size":"76376.97", "side":"BUY", "hash":"b98b7eb881cc2077b215e10b79d8094a49785191", "best_bid":"0.18", "best_ask":"0.19"}], "timestamp":"1789143515475", "event_type":"price_change"}
{"market":"0x876506d8b2bd7a0d3fa4fe18c024eee6e1dd81ee24c26795dadd6cfe4a7b5d0d", "asset_id":"63842529068710005716169325380315470359047749786610778647370693404952498013178", "bids":[{"price":"0.01", "size":"1103692.45"}, {"price":"0.02", "size":"3406.6"}, {"price":"0.03", "size":"70623.04"}, {"price":"0.04", "size":"60500"}, {"price":"0.05", "size":"30250"}, {"price":"0.06", "size":"39427.78"}, {"price":"0.07", "size":"35317.5"}, {"price":"0.08", "size":"10010"}, {"price":"0.09", "size":"10245.62"}, {"price":"0.1", "size":"10295"}, {"price":"0.12", "size":"18005.41"}, {"price":"0.14", "size":"5"}, {"price":"0.15", "size":"174.38"}, {"price":"0.16", "size":"100"}, {"price":"0.17", "size":"12765.59"}, {"price":"0.18", "size":"5"}, {"price":"0.2", "size":"310"}, {"price":"0.21", "size":"5"}, {"price":"0.22", "size":"6592.61"}, {"price":"0.23", "size":"9264.52"}, {"price":"0.24", "size":"30007"}, {"price":"0.26", "size":"20"}, {"price":"0.27", "size":"5950.21"}, {"price":"0.28", "size":"1051.66"}, {"price":"0.29", "size":"200"}, {"price":"0.3", "size":"1375"}, {"price":"0.31", "size":"300"}, {"price":"0.32", "size":"3834.18"}, {"price":"0.33", "size":"300"}, {"price":"0.34", "size":"20299.98"}, {"price":"0.35", "size":"100"}, {"price":"0.36", "size":"100"}, {"price":"0.37", "size":"2878.72"}, {"price":"0.38", "size":"110"}, {"price":"0.39", "size":"100"}, {"price":"0.4", "size":"100"}, {"price":"0.42", "size":"2465.92"}, {"price":"0.45", "size":"400"}, {"price":"0.46", "size":"1000"}, {"price":"0.47", "size":"2200"}, {"price":"0.48", "size":"220"}, {"price":"0.49", "size":"1000"}, {"price":"0.5", "size":"223.61"}, {"price":"0.51", "size":"750"}, {"price":"0.52", "size":"10000.01"}, {"price":"0.53", "size":"10000"}, {"price":"0.54", "size":"10075"}, {"price":"0.55", "size":"4024.99"}, {"price":"0.59", "size":"50"}, {"price":"0.6", "size":"227"}, {"price":"0.61", "size":"2409"}, {"price":"0.62", "size":"4225"}, {"price":"0.63", "size":"50010"}, {"price":"0.64", "size":"2020"}, {"price":"0.65", "size":"1015.3"}, {"price":"0.66", "size":"2284.42"}, {"price":"0.67", "size":"3200"}, {"price":"0.68", "size":"931.09"}, {"price":"0.69", "size":"2501.7"}, {"price":"0.7", "size":"3060"}, {"price":"0.71", "size":"6719.73"}, {"price":"0.72", "size":"1500"}, {"price":"0.73", "size":"11.14"}, {"price":"0.74", "size":"2000"}, {"price":"0.75", "size":"14018"}, {"price":"0.76", "size":"39432.99"}, {"price":"0.77", "size":"377789.56"}, {"price":"0.78", "size":"24485.62"}, {"price":"0.79", "size":"121320.12"}, {"price":"0.8", "size":"625637.04"}, {"price":"0.81", "size":"13613.73"}], "asks":[{"price":"0.99", "size":"2253362.07"}, {"price":"0.98", "size":"57280.6"}, {"price":"0.97", "size":"95648.36"}, {"price":"0.96", "size":"64750"}, {"price":"0.95", "size":"31642"}, {"price":"0.94", "size":"46340.08"}, {"price":"0.93", "size":"34691.41"}, {"price":"0.92", "size":"33019"}, {"price":"0.91", "size":"44610"}, {"price":"0.9", "size":"40238.51"}, {"price":"0.89", "size":"78583.18"}, {"price":"0.88", "size":"58110"}, {"price":"0.87", "size":"37050"}, {"price":"0.86", "size":"46773.03"}, {"price":"0.85", "size":"76814"}, {"price":"0.84", "size":"41869.54"}, {"price":"0.83", "size":"68968.19"}, {"price":"0.82", "size":"76376.97"}], "hash":"ddd735aa7df38d960030dc709f1779a1ac98f7fb", "timestamp":"1789143515475", "event_type":"book"}
{"market":"0x876506d8b2bd7a0d3fa4fe18c024eee6e1dd81ee24c26795dadd6cfe4a7b5d0d", "asset_id":"63842529068710005716169325380315470359047749786610778647370693404952498013178", "price":"0.82", "size":"120.585366", "fee_rate_bps":"0", "side":"BUY", "timestamp":"1789143515503", "event_type":"last_trade_price", "transaction_hash":"0x2e06a22c60a52aaa337f870cf67ab26f694da4455c80cfa9fdcda7cb62e4316d"}
{"market":"0x876506d8b2bd7a0d3fa4fe18c024eee6e1dd81ee24c26795dadd6cfe4a7b5d0d", "price_changes":[{"asset_id":"2881957189963819690709899387312951271986076905757701114514025622922000576600", "price":"0.17", "size":"68733.19", "side":"BUY", "hash":"bed81258733910eb489bb83a6a36a04cd979fc0a", "best_bid":"0.18", "best_ask":"0.19"}, {"asset_id":"63842529068710005716169325380315470359047749786610778647370693404952498013178", "price":"0.83", "size":"68733.19", "side":"SELL", "hash":"e9b5e03d28e8ca363e4f57270886b33f9becb066", "best_bid":"0.81", "best_ask":"0.82"}], "timestamp":"1789143515526", "event_type":"price_change"}
{"market":"0x876506d8b2bd7a0d3fa4fe18c024eee6e1dd81ee24c26795dadd6cfe4a7b5d0d", "price_changes":[{"asset_id":"2881957189963819690709899387312951271986076905757701114514025622922000576600", "price":"0.17", "size":"68498.19", "side":"BUY", "hash":"1845d5855aebf9bb1fb98b9dbd3f310fc94f3ac4", "best_bid":"0.18", "best_ask":"0.19"}, {"asset_id":"63842529068710005716169325380315470359047749786610778647370693404952498013178", "price":"0.83", "size":"68498.19", "side":"SELL", "hash":"ec4ed1da4fa0bf60bc9eb0f2e176355345bc223e", "best_bid":"0.81", "best_ask":"0.82"}], "timestamp":"1789143515527", "event_type":"price_change"}
{"market":"0x876506d8b2bd7a0d3fa4fe18c024eee6e1dd81ee24c26795dadd6cfe4a7b5d0d", "price_changes":[{"asset_id":"63842529068710005716169325380315470359047749786610778647370693404952498013178", "price":"0.79", "size":"120272.12", "side":"BUY", "hash":"7f300545974e6b2b21e8e0d127bcda02e19b2e78", "best_bid":"0.81", "best_ask":"0.82"}, {"asset_id":"2881957189963819690709899387312951271986076905757701114514025622922000576600", "price":"0.21", "size":"120272.12", "side":"SELL", "hash":"c84da31e5d06f2d161547caf4880bf12a208db37", "best_bid":"0.18", "best_ask":"0.19"}], "timestamp":"1789143515535", "event_type":"price_change"}
{"market":"0x876506d8b2bd7a0d3fa4fe18c024eee6e1dd81ee24c26795dadd6cfe4a7b5d0d", "price_changes":[{"asset_id":"2881957189963819690709899387312951271986076905757701114514025622922000576600", "price":"0.16", "size":"36695.54", "side":"BUY", "hash":"0a16b7cf6a127b15afbf3f6d9e20db32ffb21394", "best_bid":"0.18", "best_ask":"0.19"}, {"asset_id":"63842529068710005716169325380315470359047749786610778647370693404952498013178", "price":"0.84", "size":"36695.54", "side":"SELL", "hash":"df21ff3d79988b562de27b5e9103d65e5d1a3dc3", "best_bid":"0.81", "best_ask":"0.82"}], "timestamp":"1789143515538", "event_type":"price_change"}
{"market":"0x876506d8b2bd7a0d3fa4fe18c024eee6e1dd81ee24c26795dadd6cfe4a7b5d0d", "price_changes":[{"asset_id":"2881957189963819690709899387312951271986076905757701114514025622922000576600", "price":"0.17", "size":"68733.19", "side":"BUY", "hash":"e23a777c3a31bf8a908bd54a5015be53fa29adb6", "best_bid":"0.18", "best_ask":"0.19"}, {"asset_id":"63842529068710005716169325380315470359047749786610778647370693404952498013178", "price":"0.83", "size":"68733.19", "side":"SELL", "hash":"421dc45813a0f24bef7e4f3ab7375525d39422c3", "best_bid":"0.81", "best_ask":"0.82"}], "timestamp":"1789143515568", "event_type":"price_change"}
{"market":"0x876506d8b2bd7a0d3fa4fe18c024eee6e1dd81ee24c26795dadd6cfe4a7b5d0d", "price_changes":[{"asset_id":"2881957189963819690709899387312951271986076905757701114514025622922000576600", "price":"0.16", "size":"41869.54", "side":"BUY", "hash":"d351bb378cd94f947b4a8a068e4d8ff9a8ced2d1", "best_bid":"0.18", "best_ask":"0.19"}, {"asset_id":"63842529068710005716169325380315470359047749786610778647370693404952498013178", "price":"0.84", "size":"41869.54", "side":"SELL", "hash":"dfe533903647f2eb7e72e7e04ef4a93e21124081", "best_bid":"0.81", "best_ask":"0.82"}], "timestamp":"1789143515581", "event_type":"price_change"}
{"market":"0x876506d8b2bd7a0d3fa4fe18c024eee6e1dd81ee24c26795dadd6cfe4a7b5d0d", "price_changes":[{"asset_id":"63842529068710005716169325380315470359047749786610778647370693404952498013178", "price":"0.79", "size":"121320.12", "side":"BUY", "hash":"10cc806af42e86e4c07f6b4220681c829402181b", "best_bid":"0.81", "best_ask":"0.82"}, {"asset_id":"2881957189963819690709899387312951271986076905757701114514025622922000576600", "price":"0.21", "size":"121320.12", "side":"SELL", "hash":"11ab9789b9fac53ad63c0c6bb1b090a3a2789bf3", "best_bid":"0.18", "best_ask":"0.19"}], "timestamp":"1789143515585", "event_type":"price_change"}
{"market":"0x876506d8b2bd7a0d3fa4fe18c024eee6e1dd81ee24c26795dadd6cfe4a7b5d0d", "price_changes":[{"asset_id":"2881957189963819690709899387312951271986076905757701114514025622922000576600", "price":"0.17", "size":"68968.19", "side":"BUY", "hash":"6fad5adbdcec5d20da8580e3bb38ee0ff205a6eb", "best_bid":"0.18", "best_ask":"0.19"}, {"asset_id":"63842529068710005716169325380315470359047749786610778647370693404952498013178", "price":"0.83", "size":"68968.19", "side":"SELL", "hash":"8fede27a9ca8b49d2400c9766f8a36ca7f97c43d", "best_bid":"0.81", "best_ask":"0.82"}], "timestamp":"1789143515586", "event_type":"price_change"}
{"market":"0x876506d8b2bd7a0d3fa4fe18c024eee6e1dd81ee24c26795dadd6cfe4a7b5d0d", "price_changes":[{"asset_id":"2881957189963819690709899387312951271986076905757701114514025622922000576600", "price":"0.17", "size":"69968.19", "side":"BUY", "hash":"962fa34daca5be6c75ee57b1f3a26e5c0b0c93d4", "best_bid":"0.18", "best_ask":"0.19"}, {"asset_id":"63842529068710005716169325380315470359047749786610778647370693404952498013178", "price":"0.83", "size":"69968.19", "side":"SELL", "hash":"13271104fdcf16a480b85e46443bf29af49f5145", "best_bid":"0.81", "best_ask":"0.82"}], "timestamp":"1789143515590", "event_type":"price_change"}
{"market":"0x876506d8b2bd7a0d3fa4fe18c024eee6e1dd81ee24c26795dadd6cfe4a7b5d0d", "price_changes":[{"asset_id":"63842529068710005716169325380315470359047749786610778647370693404952498013178", "price":"0.81", "size":"13413.73", "side":"BUY", "hash":"19cd2d8d9208786eef70332c90643394e981a3ba", "best_bid":"0.81", "best_ask":"0.82"}, {"asset_id":"2881957189963819690709899387312951271986076905757701114514025622922000576600", "price":"0.19", "size":"13413.73", "side":"SELL", "hash":"e052d53a7158a80c6bfaeb5a29df537274ea38f8", "best_bid":"0.18", "best_ask":"0.19"}], "timestamp":"1789143515603", "event_type":"price_change"}
{"market":"0x876506d8b2bd7a0d3fa4fe18c024eee6e1dd81ee24c26795dadd6cfe4a7b5d0d", "price_changes":[{"asset_id":"2881957189963819690709899387312951271986076905757701114514025622922000576600", "price":"0.18", "size":"76176.97", "side":"BUY", "hash":"e052d53a7158a80c6bfaeb5a29df537274ea38f8", "best_bid":"0.18", "best_ask":"0.19"}, {"asset_id":"63842529068710005716169325380315470359047749786610778647370693404952498013178", "price":"0.82", "size":"76176.97", "side":"SELL", "hash":"19cd2d8d9208786eef70332c90643394e981a3ba", "best_bid":"0.81", "best_ask":"0.82"}], "timestamp":"1789143515603", "event_type":"price_change"}
{"market":"0x876506d8b2bd7a0d3fa4fe18c024eee6e1dd81ee24c26795dadd6cfe4a7b5d0d", "price_changes":[{"asset_id":"2881957189963819690709899387312951271986076905757701114514025622922000576600", "price":"0.17", "size":"68968.19", "side":"BUY", "hash":"90791bc1b850595b99b45cb93d7973ddd11d0fa8", "best_bid":"0.18", "best_ask":"0.19"}, {"asset_id":"63842529068710005716169325380315470359047749786610778647370693404952498013178", "price":"0.83", "size":"68968.19", "side":"SELL", "hash":"8857b33870d51947973897ad4159564e97f4c068", "best_bid":"0.81", "best_ask":"0.82"}], "timestamp":"1789143515660", "event_type":"price_change"}
{"market":"0x876506d8b2bd7a0d3fa4fe18c024eee6e1dd81ee24c26795dadd6cfe4a7b5d0d", "price_changes":[{"asset_id":"2881957189963819690709899387312951271986076905757701114514025622922000576600", "price":"0.18", "size":"76376.97", "side":"BUY", "hash":"97878e7b3f2014316b5969a9adbaba376d1489fa", "best_bid":"0.18", "best_ask":"0.19"}, {"asset_id":"63842529068710005716169325380315470359047749786610778647370693404952498013178", "price":"0.82", "size":"76376.97", "side":"SELL", "hash":"0d630685b6a60bc7385c56ac569e0d3375606854", "best_bid":"0.81", "best_ask":"0.82"}], "timestamp":"1789143515749", "event_type":"price_change"}
{"market":"0x876506d8b2bd7a0d3fa4fe18c024eee6e1dd81ee24c26795dadd6cfe4a7b5d0d", "price_changes":[{"asset_id":"63842529068710005716169325380315470359047749786610778647370693404952498013178", "price":"0.81", "size":"13613.73", "side":"BUY", "hash":"0fc62bcb6acd2f08e81e1c8f09e56f2b65e452a0", "best_bid":"0.81", "best_ask":"0.82"}, {"asset_id":"2881957189963819690709899387312951271986076905757701114514025622922000576600", "price":"0.19", "size":"13613.73", "side":"SELL", "hash":"fc1d9e6bb9c55715a1d90dc29df1061c5cd7b33a", "best_bid":"0.18", "best_ask":"0.19"}], "timestamp":"1789143515750", "event_type":"price_change"}
